Workbook

Sheet 总览
A1: 总览
A3: 蓝色格填写；灰色格自动计算。当前持仓比例按市值计算，月度购买金额按目标比例计算。
A4: 基础月投 USD | B4: 500 | D4: 每月计划日 | E4: 10 | G4: 新投入：VOO 90%＋QQQM 10%；SMH 为历史持仓，后续计划投入 0。
A7: ETF | B7: 目标比例 | C7: 基础计划 USD | D7: 现价 USD／份 | E7: 价格日期 | F7: 当前份额 | G7: 持仓成本 USD | H7: 平均成本／份 | I7: 市值 USD | J7: 未实现盈亏 USD | K7: 持仓收益率 | L7: 市值占比 | M7: 偏离目标 | N7: 状态
A8: VOO | B8: 0.9 | C8: =$B$4*B8 -> 450 | D8: 712.32 | E8: 46301 | F8: =IF(COUNTIF(交易记录!$B$6:$B$605,A8)=0,0,IF(COUNTIFS(交易记录!$B$6:$B$605,A8,交易记录!$K$6:$K$605,"<>已记录")>0,"",SUMIF(交易记录!$B$6:$B$605,A8,交易记录!$I$6:$I$605))) -> 0.5373 | G8: =IF(F8="","",SUMIF(交易记录!$B$6:$B$605,A8,交易记录!$H$6:$H$605)) -> 375 | H8: =IF(OR(F8="",F8=0),"",G8/F8) -> 697.93412 | I8: =IF(F8="","",IF(F8=0,0,IF(OR(D8="",D8<=0),"",F8*D8))) -> 382.72954 | J8: =IF(I8="","",I8-G8) -> 7.729536 | K8: =IF(OR(J8="",G8=0),"",J8/G8) -> 0.020612096 | L8: =IF(OR($I$12="",$I$12=0,I8=""),"",I8/$I$12) -> 0.73807916 | M8: =IF(L8="","",L8-B8) -> -0.16192084 | N8: =IF(COUNTIFS(交易记录!$B$6:$B$605,A8,交易记录!$K$6:$K$605,"<>已记录")>0,"待补交易信息",IF(F8=0,"无持仓",IF(D8="","待填现价",IF(E8="","待填价格日期","已计算")))) -> 已计算
A9: QQQM | B9: 0.1 | C9: =$B$4*B9 -> 50 | D9: 311.4 | E9: 46301 | F9: =IF(COUNTIF(交易记录!$B$6:$B$605,A9)=0,0,IF(COUNTIFS(交易记录!$B$6:$B$605,A9,交易记录!$K$6:$K$605,"<>已记录")>0,"",SUMIF(交易记录!$B$6:$B$605,A9,交易记录!$I$6:$I$605))) -> 0.256 | G9: =IF(F9="","",SUMIF(交易记录!$B$6:$B$605,A9,交易记录!$H$6:$H$605)) -> 75 | H9: =IF(OR(F9="",F9=0),"",G9/F9) -> 292.96875 | I9: =IF(F9="","",IF(F9=0,0,IF(OR(D9="",D9<=0),"",F9*D9))) -> 79.7184 | J9: =IF(I9="","",I9-G9) -> 4.7184 | K9: =IF(OR(J9="",G9=0),"",J9/G9) -> 0.062912 | L9: =IF(OR($I$12="",$I$12=0,I9=""),"",I9/$I$12) -> 0.15373386 | M9: =IF(L9="","",L9-B9) -> 0.053733862 | N9: =IF(COUNTIFS(交易记录!$B$6:$B$605,A9,交易记录!$K$6:$K$605,"<>已记录")>0,"待补交易信息",IF(F9=0,"无持仓",IF(D9="","待填现价",IF(E9="","待填价格日期","已计算")))) -> 已计算
A10: SMH | B10: 0 | C10: =$B$4*B10 -> 0 | D10: 633.9 | E10: 46301 | F10: =IF(COUNTIF(交易记录!$B$6:$B$605,A10)=0,0,IF(COUNTIFS(交易记录!$B$6:$B$605,A10,交易记录!$K$6:$K$605,"<>已记录")>0,"",SUMIF(交易记录!$B$6:$B$605,A10,交易记录!$I$6:$I$605))) -> 0.0885 | G10: =IF(F10="","",SUMIF(交易记录!$B$6:$B$605,A10,交易记录!$H$6:$H$605)) -> 50 | H10: =IF(OR(F10="",F10=0),"",G10/F10) -> 564.97175 | I10: =IF(F10="","",IF(F10=0,0,IF(OR(D10="",D10<=0),"",F10*D10))) -> 56.10015 | J10: =IF(I10="","",I10-G10) -> 6.10015 | K10: =IF(OR(J10="",G10=0),"",J10/G10) -> 0.122003 | L10: =IF(OR($I$12="",$I$12=0,I10=""),"",I10/$I$12) -> 0.10818698 | M10: =IF(L10="","",L10-B10) -> 0.10818698 | N10: =IF(COUNTIFS(交易记录!$B$6:$B$605,A10,交易记录!$K$6:$K$605,"<>已记录")>0,"待补交易信息",IF(F10=0,"无持仓",IF(D10="","待填现价",IF(E10="","待填价格日期","已计算")))) -> 已计算
A12: 合计 | B12: =SUM(B8:B10) -> 1 | C12: =SUM(C8:C10) -> 500 | G12: =IF(COUNT(G8:G10)<3,"",SUM(G8:G10)) -> 500 | I12: =IF(COUNT(I8:I10)<3,"",SUM(I8:I10)) -> 518.54809 | J12: =IF(COUNT(J8:J10)<3,"",SUM(J8:J10)) -> 18.548086 | K12: =IF(OR(J12="",G12=0),"",J12/G12) -> 0.037096172
A14: 现金 USD | B14: 1804.86 | D14: 总值 USD | E14: =IF(OR(I12="",B14=""),"",I12+B14) -> 2323.4081 | G14: 现金请按嘉信余额手动填写；账户总值＝ETF 市值＋现金。
A16: 累计买入 | C16: =SUMIF(交易记录!C6:C605,"买入",交易记录!D6:D605)+SUMIF(交易记录!C6:C605,"买入",交易记录!E6:E605) -> 500 | D16: 到账 USD | E16: =SUMIFS(换汇记录!L6:L246,换汇记录!F6:F246,"嘉信证券")+SUMIFS(入金记录!G6:G245,入金记录!F6:F245,"嘉信证券",入金记录!D6:D245,"USD",入金记录!C6:C245,"<>嘉信证券",入金记录!H6:H245,">0") -> 2303.8 | G16: 税后分红 | I16: =SUM(分红记录!F6:F245) -> 0 | J16: 已实现盈亏 | M16: =IF(COUNTIFS(交易记录!C6:C605,"卖出",交易记录!K6:K605,"<>已记录")>0,"",SUM(交易记录!J6:J605)) -> 0
A18: 每月先填回撤计划指数数据，再分别记录换汇、转账和ETF成交。已保留你填写的各笔金额、日期、账户、备注、份额及行情；美元到账按实际终端记录汇总，避免重复计入。
A21: 说明：持仓收益率为未实现盈亏 ÷ 当前持仓成本，并非年化收益率。买卖成本采用移动加权平均法作投资分析；券商成交记录和税务成本口径可能不同。已有 SMH 只记录，不触发卖出。
A24: 本表执行500／750／1000美元回撤计划，额外预算累计5000美元，实际耗尽后回到500。目标比例90%／10%；SMH历史持仓继续记录。修改基础额、预算或目标会重算计划及统计，请先备份。
A28: 额外预算 USD | C28: =回撤计划!E4 -> 5000 | E28: 实际加投按回撤计划记录扣减。分红再投／其他买入在交易记录P列分类；必要时在回撤计划O列修正实际使用额外预算。嘉信可用现金仍按实际账户余额手动更新。
A29: 额外已用 USD | C29: =回撤计划!K4 -> 0
A30: 额外剩余 USD | C30: =回撤计划!N4 -> 5000

Sheet 回撤计划
A1: 回撤计划
A3: 10%以下500；10%至不足20%为750；20%及以上1000。5000美元仅约束额外投入，按实际买入扣减，用完恢复500。每月10日交易前填最近已结束美股交易日收盘；遇休市顺延。
A4: 基础月投 USD | B4: =总览!B4 -> 500 | D4: 额外预算 USD | E4: 5000 | G4: 起始历史高收盘 | H4: 7794.35 | J4: 额外已用 USD | K4: =SUM(P9:P128) -> 0 | M4: 额外剩余 USD | N4: =MAX(0,E4-K4) -> 5000
A5: 先在H4填写核对过的起始历史最高收盘；后续出现更高收盘，填对应月D列（当月收盘创新高也会自动上调）。高点不随反弹下调；预算不自动重置。
A6: 实际定投仅计VOO／QQQM买入及手续费，排除P列“分红再投／其他”。额外参考=max(当月实际定投−500,0)；若资金用途不同，在O列填实际动用预算（0也有效）。交易未记入前不扣预算。
A8: 计划日期 | B8: 观察收盘日 | C8: 标普500收盘 | D8: 新历史高收盘 | E8: 沿用历史高点 | F8: 回撤幅度 | G8: 标准月额 USD | H8: 月初加投余款 | I8: 计划额外 USD | J8: 本月合计 USD | K8: VOO计划 USD | L8: QQQM计划 USD | M8: 实际定投 USD | N8: 额外支出参考 | O8: 实际额外（选填） | P8: 已用额外 USD | Q8: 月底加投余款 | R8: 状态 | S8: 备注
A9: =月度计划!A6 -> 46305 | E9: =IF(MAX($H$4,$H$4,D9)<=0,"",MAX($H$4,$H$4,D9,C9)) -> 7794.35 | F9: =IF(AND(ISNUMBER(B9),ISNUMBER(C9),C9>0,ISNUMBER(E9),E9>0),MAX(0,1-C9/E9),"") | G9: =IF(F9="","",IF(ROUND(F9,10)<0.1,$B$4,IF(ROUND(F9,10)<0.2,$B$4+250,$B$4+500))) | H9: =MAX(0,$E$4) -> 5000 | I9: =IF(G9="",0,MIN(MAX(0,G9-$B$4),H9)) -> 0 | J9: =$B$4+I9 -> 500 | K9: =J9*总览!$B$8 -> 450 | L9: =J9*总览!$B$9 -> 50 | M9: =SUMIFS(交易记录!$D$6:$D$605,交易记录!$A$6:$A$605,">="&DATE(YEAR(A9),MONTH(A9),1),交易记录!$A$6:$A$605,"<"&DATE(YEAR(A9),MONTH(A9)+1,1),交易记录!$C$6:$C$605,"买入",交易记录!$P$6:$P$605,"<>分红再投",交易记录!$P$6:$P$605,"<>其他",交易记录!$B$6:$B$605,"VOO")+SUMIFS(交易记录!$D$6:$D$605,交易记录!$A$6:$A$605,">="&DATE(YEAR(A9),MONTH(A9),1),交易记录!$A$6:$A$605,"<"&DATE(YEAR(A9),MONTH(A9)+1,1),交易记录!$C$6:$C$605,"买入",交易记录!$P$6:$P$605,"<>分红再投",交易记录!$P$6:$P$605,"<>其他",交易记录!$B$6:$B$605,"QQQM")+SUMIFS(交易记录!$E$6:$E$605,交易记录!$A$6:$A$605,">="&DATE(YEAR(A9),MONTH(A9),1),交易记录!$A$6:$A$605,"<"&DATE(YEAR(A9),MONTH(A9)+1,1),交易记录!$C$6:$C$605,"买入",交易记录!$P$6:$P$605,"<>分红再投",交易记录!$P$6:$P$605,"<>其他",交易记录!$B$6:$B$605,"VOO")+SUMIFS(交易记录!$E$6:$E$605,交易记录!$A$6:$A$605,">="&DATE(YEAR(A9),MONTH(A9),1),交易记录!$A$6:$A$605,"<"&DATE(YEAR(A9),MONTH(A9)+1,1),交易记录!$C$6:$C$605,"买入",交易记录!$P$6:$P$605,"<>分红再投",交易记录!$P$6:$P$605,"<>其他",交易记录!$B$6:$B$605,"QQQM") -> 0 | N9: =MAX(0,M9-$B$4) -> 0 | P9: =IF(O9="",N9,O9) -> 0 | Q9: =MAX(0,H9-P9) -> 5000 | R9: =IF(P9>H9+0.005,"实际加投超剩余预算，请核对",IF(H9=0,"预算用完：基础定投",IF(F9="","待补指数收盘／历史基准；先列基础额",IF(AND(B9>A9,M9=0),"核对观察日是否在实际交易前",IF(AND(O9<>"",ABS(O9-N9)>0.005),"已按手填额外支出扣预算",IF(M9=0,"已计算，尚未记录买入",IF(ABS(M9-J9)<0.01,"已按计划记录","实际定投与计划有差额"))))))) -> 待补指数收盘／历史基准；先列基础额
A10: =月度计划!A7 -> 46336 | E10: =IF(MAX($H$4,E9,D10)<=0,"",MAX($H$4,E9,D10,C10)) -> 7794.35 | F10: =IF(AND(ISNUMBER(B10),ISNUMBER(C10),C10>0,ISNUMBER(E10),E10>0),MAX(0,1-C10/E10),"") | G10: =IF(F10="","",IF(ROUND(F10,10)<0.1,$B$4,IF(ROUND(F10,10)<0.2,$B$4+250,$B$4+500))) | H10: =MAX(0,$E$4-SUM($P$9:P9)) -> 5000 | I10: =IF(G10="",0,MIN(MAX(0,G10-$B$4),H10)) -> 0 | J10: =$B$4+I10 -> 500 | K10: =J10*总览!$B$8 -> 450 | L10: =J10*总览!$B$9 -> 50 | M10: =SUMIFS(交易记录!$D$6:$D$605,交易记录!$A$6:$A$605,">="&DATE(YEAR(A10),MONTH(A10),1),交易记录!$A$6:$A$605,"<"&DATE(YEAR(A10),MONTH(A10)+1,1),交易记录!$C$6:$C$605,"买入",交易记录!$P$6:$P$605,"<>分红再投",交易记录!$P$6:$P$605,"<>其他",交易记录!$B$6:$B$605,"VOO")+SUMIFS(交易记录!$D$6:$D$605,交易记录!$A$6:$A$605,">="&DATE(YEAR(A10),MONTH(A10),1),交易记录!$A$6:$A$605,"<"&DATE(YEAR(A10),MONTH(A10)+1,1),交易记录!$C$6:$C$605,"买入",交易记录!$P$6:$P$605,"<>分红再投",交易记录!$P$6:$P$605,"<>其他",交易记录!$B$6:$B$605,"QQQM")+SUMIFS(交易记录!$E$6:$E$605,交易记录!$A$6:$A$605,">="&DATE(YEAR(A10),MONTH(A10),1),交易记录!$A$6:$A$605,"<"&DATE(YEAR(A10),MONTH(A10)+1,1),交易记录!$C$6:$C$605,"买入",交易记录!$P$6:$P$605,"<>分红再投",交易记录!$P$6:$P$605,"<>其他",交易记录!$B$6:$B$605,"VOO")+SUMIFS(交易记录!$E$6:$E$605,交易记录!$A$6:$A$605,">="&DATE(YEAR(A10),MONTH(A10),1),交易记录!$A$6:$A$605,"<"&DATE(YEAR(A10),MONTH(A10)+1,1),交易记录!$C$6:$C$605,"买入",交易记录!$P$6:$P$605,"<>分红再投",交易记录!$P$6:$P$605,"<>其他",交易记录!$B$6:$B$605,"QQQM") -> 0 | N10: =MAX(0,M10-$B$4) -> 0 | P10: =IF(O10="",N10,O10) -> 0 | Q10: =MAX(0,H10-P10) -> 5000 | R10: =IF(P10>H10+0.005,"实际加投超剩余预算，请核对",IF(H10=0,"预算用完：基础定投",IF(F10="","待补指数收盘／历史基准；先列基础额",IF(AND(B10>A10,M10=0),"核对观察日是否在实际交易前",IF(AND(O10<>"",ABS(O10-N10)>0.005),"已按手填额外支出扣预算",IF(M10=0,"已计算，尚未记录买入",IF(ABS(M10-J10)<0.01,"已按计划记录","实际定投与计划有差额"))))))) -> 待补指数收盘／历史基准；先列基础额
A11: =月度计划!A8 -> 46366 | E11: =IF(MAX($H$4,E10,D11)<=0,"",MAX($H$4,E10,D11,C11)) -> 7794.35 | F11: =IF(AND(ISNUMBER(B11),ISNUMBER(C11),C11>0,ISNUMBER(E11),E11>0),MAX(0,1-C11/E11),"") | G11: =IF(F11="","",IF(ROUND(F11,10)<0.1,$B$4,IF(ROUND(F11,10)<0.2,$B$4+250,$B$4+500))) | H11: =MAX(0,$E$4-SUM($P$9:P10)) -> 5000 | I11: =IF(G11="",0,MIN(MAX(0,G11-$B$4),H11)) -> 0 | J11: =$B$4+I11 -> 500 | K11: =J11*总览!$B$8 -> 450 | L11: =J11*总览!$B$9 -> 50 | M11: =SUMIFS(交易记录!$D$6:$D$605,交易记录!$A$6:$A$605,">="&DATE(YEAR(A11),MONTH(A11),1),交易记录!$A$6:$A$605,"<"&DATE(YEAR(A11),MONTH(A11)+1,1),交易记录!$C$6:$C$605,"买入",交易记录!$P$6:$P$605,"<>分红再投",交易记录!$P$6:$P$605,"<>其他",交易记录!$B$6:$B$605,"VOO")+SUMIFS(交易记录!$D$6:$D$605,交易记录!$A$6:$A$605,">="&DATE(YEAR(A11),MONTH(A11),1),交易记录!$A$6:$A$605,"<"&DATE(YEAR(A11),MONTH(A11)+1,1),交易记录!$C$6:$C$605,"买入",交易记录!$P$6:$P$605,"<>分红再投",交易记录!$P$6:$P$605,"<>其他",交易记录!$B$6:$B$605,"QQQM")+SUMIFS(交易记录!$E$6:$E$605,交易记录!$A$6:$A$605,">="&DATE(YEAR(A11),MONTH(A11),1),交易记录!$A$6:$A$605,"<"&DATE(YEAR(A11),MONTH(A11)+1,1),交易记录!$C$6:$C$605,"买入",交易记录!$P$6:$P$605,"<>分红再投",交易记录!$P$6:$P$605,"<>其他",交易记录!$B$6:$B$605,"VOO")+SUMIFS(交易记录!$E$6:$E$605,交易记录!$A$6:$A$605,">="&DATE(YEAR(A11),MONTH(A11),1),交易记录!$A$6:$A$605,"<"&DATE(YEAR(A11),MONTH(A11)+1,1),交易记录!$C$6:$C$605,"买入",交易记录!$P$6:$P$605,"<>分红再投",交易记录!$P$6:$P$605,"<>其他",交易记录!$B$6:$B$605,"QQQM") -> 0 | N11: =MAX(0,M11-$B$4) -> 0 | P11: =IF(O11="",N11,O11) -> 0 | Q11: =MAX(0,H11-P11) -> 5000 | R11: =IF(P11>H11+0.005,"实际加投超剩余预算，请核对",IF(H11=0,"预算用完：基础定投",IF(F11="","待补指数收盘／历史基准；先列基础额",IF(AND(B11>A11,M11=0),"核对观察日是否在实际交易前",IF(AND(O11<>"",ABS(O11-N11)>0.005),"已按手填额外支出扣预算",IF(M11=0,"已计算，尚未记录买入",IF(ABS(M11-J11)<0.01,"已按计划记录","实际定投与计划有差额"))))))) -> 待补指数收盘／历史基准；先列基础额
A12: =月度计划!A9 -> 46397 | E12: =IF(MAX($H$4,E11,D12)<=0,"",MAX($H$4,E11,D12,C12)) -> 7794.35 | F12: =IF(AND(ISNUMBER(B12),ISNUMBER(C12),C12>0,ISNUMBER(E12),E12>0),MAX(0,1-C12/E12),"") | G12: =IF(F12="","",IF(ROUND(F12,10)<0.1,$B$4,IF(ROUND(F12,10)<0.2,$B$4+250,$B$4+500))) | H12: =MAX(0,$E$4-SUM($P$9:P11)) -> 5000 | I12: =IF(G12="",0,MIN(MAX(0,G12-$B$4),H12)) -> 0 | J12: =$B$4+I12 -> 500 | K12: =J12*总览!$B$8 -> 450 | L12: =J12*总览!$B$9 -> 50 | M12: =SUMIFS(交易记录!$D$6:$D$605,交易记录!$A$6:$A$605,">="&DATE(YEAR(A12),MONTH(A12),1),交易记录!$A$6:$A$605,"<"&DATE(YEAR(A12),MONTH(A12)+1,1),交易记录!$C$6:$C$605,"买入",交易记录!$P$6:$P$605,"<>分红再投",交易记录!$P$6:$P$605,"<>其他",交易记录!$B$6:$B$605,"VOO")+SUMIFS(交易记录!$D$6:$D$605,交易记录!$A$6:$A$605,">="&DATE(YEAR(A12),MONTH(A12),1),交易记录!$A$6:$A$605,"<"&DATE(YEAR(A12),MONTH(A12)+1,1),交易记录!$C$6:$C$605,"买入",交易记录!$P$6:$P$605,"<>分红再投",交易记录!$P$6:$P$605,"<>其他",交易记录!$B$6:$B$605,"QQQM")+SUMIFS(交易记录!$E$6:$E$605,交易记录!$A$6:$A$605,">="&DATE(YEAR(A12),MONTH(A12),1),交易记录!$A$6:$A$605,"<"&DATE(YEAR(A12),MONTH(A12)+1,1),交易记录!$C$6:$C$605,"买入",交易记录!$P$6:$P$605,"<>分红再投",交易记录!$P$6:$P$605,"<>其他",交易记录!$B$6:$B$605,"VOO")+SUMIFS(交易记录!$E$6:$E$605,交易记录!$A$6:$A$605,">="&DATE(YEAR(A12),MONTH(A12),1),交易记录!$A$6:$A$605,"<"&DATE(YEAR(A12),MONTH(A12)+1,1),交易记录!$C$6:$C$605,"买入",交易记录!$P$6:$P$605,"<>分红再投",交易记录!$P$6:$P$605,"<>其他",交易记录!$B$6:$B$605,"QQQM") -> 0 | N12: =MAX(0,M12-$B$4) -> 0 | P12: =IF(O12="",N12,O12) -> 0 | Q12: =MAX(0,H12-P12) -> 5000 | R12: =IF(P12>H12+0.005,"实际加投超剩余预算，请核对",IF(H12=0,"预算用完：基础定投",IF(F12="","待补指数收盘／历史基准；先列基础额",IF(AND(B12>A12,M12=0),"核对观察日是否在实际交易前",IF(AND(O12<>"",ABS(O12-N12)>0.005),"已按手填额外支出扣预算",IF(M12=0,"已计算，尚未记录买入",IF(ABS(M12-J12)<0.01,"已按计划记录","实际定投与计划有差额"))))))) -> 待补指数收盘／历史基准；先列基础额
A13: =月度计划!A10 -> 46428 | E13: =IF(MAX($H$4,E12,D13)<=0,"",MAX($H$4,E12,D13,C13)) -> 7794.35 | F13: =IF(AND(ISNUMBER(B13),ISNUMBER(C13),C13>0,ISNUMBER(E13),E13>0),MAX(0,1-C13/E13),"") | G13: =IF(F13="","",IF(ROUND(F13,10)<0.1,$B$4,IF(ROUND(F13,10)<0.2,$B$4+250,$B$4+500))) | H13: =MAX(0,$E$4-SUM($P$9:P12)) -> 5000 | I13: =IF(G13="",0,MIN(MAX(0,G13-$B$4),H13)) -> 0 | J13: =$B$4+I13 -> 500 | K13: =J13*总览!$B$8 -> 450 | L13: =J13*总览!$B$9 -> 50 | M13: =SUMIFS(交易记录!$D$6:$D$605,交易记录!$A$6:$A$605,">="&DATE(YEAR(A13),MONTH(A13),1),交易记录!$A$6:$A$605,"<"&DATE(YEAR(A13),MONTH(A13)+1,1),交易记录!$C$6:$C$605,"买入",交易记录!$P$6:$P$605,"<>分红再投",交易记录!$P$6:$P$605,"<>其他",交易记录!$B$6:$B$605,"VOO")+SUMIFS(交易记录!$D$6:$D$605,交易记录!$A$6:$A$605,">="&DATE(YEAR(A13),MONTH(A13),1),交易记录!$A$6:$A$605,"<"&DATE(YEAR(A13),MONTH(A13)+1,1),交易记录!$C$6:$C$605,"买入",交易记录!$P$6:$P$605,"<>分红再投",交易记录!$P$6:$P$605,"<>其他",交易记录!$B$6:$B$605,"QQQM")+SUMIFS(交易记录!$E$6:$E$605,交易记录!$A$6:$A$605,">="&DATE(YEAR(A13),MONTH(A13),1),交易记录!$A$6:$A$605,"<"&DATE(YEAR(A13),MONTH(A13)+1,1),交易记录!$C$6:$C$605,"买入",交易记录!$P$6:$P$605,"<>分红再投",交易记录!$P$6:$P$605,"<>其他",交易记录!$B$6:$B$605,"VOO")+SUMIFS(交易记录!$E$6:$E$605,交易记录!$A$6:$A$605,">="&DATE(YEAR(A13),MONTH(A13),1),交易记录!$A$6:$A$605,"<"&DATE(YEAR(A13),MONTH(A13)+1,1),交易记录!$C$6:$C$605,"买入",交易记录!$P$6:$P$605,"<>分红再投",交易记录!$P$6:$P$605,"<>其他",交易记录!$B$6:$B$605,"QQQM") -> 0 | N13: =MAX(0,M13-$B$4) -> 0 | P13: =IF(O13="",N13,O13) -> 0 | Q13: =MAX(0,H13-P13) -> 5000 | R13: =IF(P13>H13+0.005,"实际加投超剩余预算，请核对",IF(H13=0,"预算用完：基础定投",IF(F13="","待补指数收盘／历史基准；先列基础额",IF(AND(B13>A13,M13=0),"核对观察日是否在实际交易前",IF(AND(O13<>"",ABS(O13-N13)>0.005),"已按手填额外支出扣预算",IF(M13=0,"已计算，尚未记录买入",IF(ABS(M13-J13)<0.01,"已按计划记录","实际定投与计划有差额"))))))) -> 待补指数收盘／历史基准；先列基础额
A14: =月度计划!A11 -> 46456 | E14: =IF(MAX($H$4,E13,D14)<=0,"",MAX($H$4,E13,D14,C14)) -> 7794.35 | F14: =IF(AND(ISNUMBER(B14),ISNUMBER(C14),C14>0,ISNUMBER(E14),E14>0),MAX(0,1-C14/E14),"") | G14: =IF(F14="","",IF(ROUND(F14,10)<0.1,$B$4,IF(ROUND(F14,10)<0.2,$B$4+250,$B$4+500))) | H14: =MAX(0,$E$4-SUM($P$9:P13)) -> 5000 | I14: =IF(G14="",0,MIN(MAX(0,G14-$B$4),H14)) -> 0 | J14: =$B$4+I14 -> 500 | K14: =J14*总览!$B$8 -> 450 | L14: =J14*总览!$B$9 -> 50 | M14: =SUMIFS(交易记录!$D$6:$D$605,交易记录!$A$6:$A$605,">="&DATE(YEAR(A14),MONTH(A14),1),交易记录!$A$6:$A$605,"<"&DATE(YEAR(A14),MONTH(A14)+1,1),交易记录!$C$6:$C$605,"买入",交易记录!$P$6:$P$605,"<>分红再投",交易记录!$P$6:$P$605,"<>其他",交易记录!$B$6:$B$605,"VOO")+SUMIFS(交易记录!$D$6:$D$605,交易记录!$A$6:$A$605,">="&DATE(YEAR(A14),MONTH(A14),1),交易记录!$A$6:$A$605,"<"&DATE(YEAR(A14),MONTH(A14)+1,1),交易记录!$C$6:$C$605,"买入",交易记录!$P$6:$P$605,"<>分红再投",交易记录!$P$6:$P$605,"<>其他",交易记录!$B$6:$B$605,"QQQM")+SUMIFS(交易记录!$E$6:$E$605,交易记录!$A$6:$A$605,">="&DATE(YEAR(A14),MONTH(A14),1),交易记录!$A$6:$A$605,"<"&DATE(YEAR(A14),MONTH(A14)+1,1),交易记录!$C$6:$C$605,"买入",交易记录!$P$6:$P$605,"<>分红再投",交易记录!$P$6:$P$605,"<>其他",交易记录!$B$6:$B$605,"VOO")+SUMIFS(交易记录!$E$6:$E$605,交易记录!$A$6:$A$605,">="&DATE(YEAR(A14),MONTH(A14),1),交易记录!$A$6:$A$605,"<"&DATE(YEAR(A14),MONTH(A14)+1,1),交易记录!$C$6:$C$605,"买入",交易记录!$P$6:$P$605,"<>分红再投",交易记录!$P$6:$P$605,"<>其他",交易记录!$B$6:$B$605,"QQQM") -> 0 | N14: =MAX(0,M14-$B$4) -> 0 | P14: =IF(O14="",N14,O14) -> 0 | Q14: =MAX(0,H14-P14) -> 5000 | R14: =IF(P14>H14+0.005,"实际加投超剩余预算，请核对",IF(H14=0,"预算用完：基础定投",IF(F14="","待补指数收盘／历史基准；先列基础额",IF(AND(B14>A14,M14=0),"核对观察日是否在实际交易前",IF(AND(O14<>"",ABS(O14-N14)>0.005),"已按手填额外支出扣预算",IF(M14=0,"已计算，尚未记录买入",IF(ABS(M14-J14)<0.01,"已按计划记录","实际定投与计划有差额"))))))) -> 待补指数收盘／历史基准；先列基础额
A15: =月度计划!A12 -> 46487 | E15: =IF(MAX($H$4,E14,D15)<=0,"",MAX($H$4,E14,D15,C15)) -> 7794.35 | F15: =IF(AND(ISNUMBER(B15),ISNUMBER(C15),C15>0,ISNUMBER(E15),E15>0),MAX(0,1-C15/E15),"") | G15: =IF(F15="","",IF(ROUND(F15,10)<0.1,$B$4,IF(ROUND(F15,10)<0.2,$B$4+250,$B$4+500))) | H15: =MAX(0,$E$4-SUM($P$9:P14)) -> 5000 | I15: =IF(G15="",0,MIN(MAX(0,G15-$B$4),H15)) -> 0 | J15: =$B$4+I15 -> 500 | K15: =J15*总览!$B$8 -> 450 | L15: =J15*总览!$B$9 -> 50 | M15: =SUMIFS(交易记录!$D$6:$D$605,交易记录!$A$6:$A$605,">="&DATE(YEAR(A15),MONTH(A15),1),交易记录!$A$6:$A$605,"<"&DATE(YEAR(A15),MONTH(A15)+1,1),交易记录!$C$6:$C$605,"买入",交易记录!$P$6:$P$605,"<>分红再投",交易记录!$P$6:$P$605,"<>其他",交易记录!$B$6:$B$605,"VOO")+SUMIFS(交易记录!$D$6:$D$605,交易记录!$A$6:$A$605,">="&DATE(YEAR(A15),MONTH(A15),1),交易记录!$A$6:$A$605,"<"&DATE(YEAR(A15),MONTH(A15)+1,1),交易记录!$C$6:$C$605,"买入",交易记录!$P$6:$P$605,"<>分红再投",交易记录!$P$6:$P$605,"<>其他",交易记录!$B$6:$B$605,"QQQM")+SUMIFS(交易记录!$E$6:$E$605,交易记录!$A$6:$A$605,">="&DATE(YEAR(A15),MONTH(A15),1),交易记录!$A$6:$A$605,"<"&DATE(YEAR(A15),MONTH(A15)+1,1),交易记录!$C$6:$C$605,"买入",交易记录!$P$6:$P$605,"<>分红再投",交易记录!$P$6:$P$605,"<>其他",交易记录!$B$6:$B$605,"VOO")+SUMIFS(交易记录!$E$6:$E$605,交易记录!$A$6:$A$605,">="&DATE(YEAR(A15),MONTH(A15),1),交易记录!$A$6:$A$605,"<"&DATE(YEAR(A15),MONTH(A15)+1,1),交易记录!$C$6:$C$605,"买入",交易记录!$P$6:$P$605,"<>分红再投",交易记录!$P$6:$P$605,"<>其他",交易记录!$B$6:$B$605,"QQQM") -> 0 | N15: =MAX(0,M15-$B$4) -> 0 | P15: =IF(O15="",N15,O15) -> 0 | Q15: =MAX(0,H15-P15) -> 5000 | R15: =IF(P15>H15+0.005,"实际加投超剩余预算，请核对",IF(H15=0,"预算用完：基础定投",IF(F15="","待补指数收盘／历史基准；先列基础额",IF(AND(B15>A15,M15=0),"核对观察日是否在实际交易前",IF(AND(O15<>"",ABS(O15-N15)>0.005),"已按手填额外支出扣预算",IF(M15=0,"已计算，尚未记录买入",IF(ABS(M15-J15)<0.01,"已按计划记录","实际定投与计划有差额"))))))) -> 待补指数收盘／历史基准；先列基础额
A16: =月度计划!A13 -> 46517 | E16: =IF(MAX($H$4,E15,D16)<=0,"",MAX($H$4,E15,D16,C16)) -> 7794.35 | F16: =IF(AND(ISNUMBER(B16),ISNUMBER(C16),C16>0,ISNUMBER(E16),E16>0),MAX(0,1-C16/E16),"") | G16: =IF(F16="","",IF(ROUND(F16,10)<0.1,$B$4,IF(ROUND(F16,10)<0.2,$B$4+250,$B$4+500))) | H16: =MAX(0,$E$4-SUM($P$9:P15)) -> 5000 | I16: =IF(G16="",0,MIN(MAX(0,G16-$B$4),H16)) -> 0 | J16: =$B$4+I16 -> 500 | K16: =J16*总览!$B$8 -> 450 | L16: =J16*总览!$B$9 -> 50 | M16: =SUMIFS(交易记录!$D$6:$D$605,交易记录!$A$6:$A$605,">="&DATE(YEAR(A16),MONTH(A16),1),交易记录!$A$6:$A$605,"<"&DATE(YEAR(A16),MONTH(A16)+1,1),交易记录!$C$6:$C$605,"买入",交易记录!$P$6:$P$605,"<>分红再投",交易记录!$P$6:$P$605,"<>其他",交易记录!$B$6:$B$605,"VOO")+SUMIFS(交易记录!$D$6:$D$605,交易记录!$A$6:$A$605,">="&DATE(YEAR(A16),MONTH(A16),1),交易记录!$A$6:$A$605,"<"&DATE(YEAR(A16),MONTH(A16)+1,1),交易记录!$C$6:$C$605,"买入",交易记录!$P$6:$P$605,"<>分红再投",交易记录!$P$6:$P$605,"<>其他",交易记录!$B$6:$B$605,"QQQM")+SUMIFS(交易记录!$E$6:$E$605,交易记录!$A$6:$A$605,">="&DATE(YEAR(A16),MONTH(A16),1),交易记录!$A$6:$A$605,"<"&DATE(YEAR(A16),MONTH(A16)+1,1),交易记录!$C$6:$C$605,"买入",交易记录!$P$6:$P$605,"<>分红再投",交易记录!$P$6:$P$605,"<>其他",交易记录!$B$6:$B$605,"VOO")+SUMIFS(交易记录!$E$6:$E$605,交易记录!$A$6:$A$605,">="&DATE(YEAR(A16),MONTH(A16),1),交易记录!$A$6:$A$605,"<"&DATE(YEAR(A16),MONTH(A16)+1,1),交易记录!$C$6:$C$605,"买入",交易记录!$P$6:$P$605,"<>分红再投",交易记录!$P$6:$P$605,"<>其他",交易记录!$B$6:$B$605,"QQQM") -> 0 | N16: =MAX(0,M16-$B$4) -> 0 | P16: =IF(O16="",N16,O16) -> 0 | Q16: =MAX(0,H16-P16) -> 5000 | R16: =IF(P16>H16+0.005,"实际加投超剩余预算，请核对",IF(H16=0,"预算用完：基础定投",IF(F16="","待补指数收盘／历史基准；先列基础额",IF(AND(B16>A16,M16=0),"核对观察日是否在实际交易前",IF(AND(O16<>"",ABS(O16-N16)>0.005),"已按手填额外支出扣预算",IF(M16=0,"已计算，尚未记录买入",IF(ABS(M16-J16)<0.01,"已按计划记录","实际定投与计划有差额"))))))) -> 待补指数收盘／历史基准；先列基础额
A17: =月度计划!A14 -> 46548 | E17: =IF(MAX($H$4,E16,D17)<=0,"",MAX($H$4,E16,D17,C17)) -> 7794.35 | F17: =IF(AND(ISNUMBER(B17),ISNUMBER(C17),C17>0,ISNUMBER(E17),E17>0),MAX(0,1-C17/E17),"") | G17: =IF(F17="","",IF(ROUND(F17,10)<0.1,$B$4,IF(ROUND(F17,10)<0.2,$B$4+250,$B$4+500))) | H17: =MAX(0,$E$4-SUM($P$9:P16)) -> 5000 | I17: =IF(G17="",0,MIN(MAX(0,G17-$B$4),H17)) -> 0 | J17: =$B$4+I17 -> 500 | K17: =J17*总览!$B$8 -> 450 | L17: =J17*总览!$B$9 -> 50 | M17: =SUMIFS(交易记录!$D$6:$D$605,交易记录!$A$6:$A$605,">="&DATE(YEAR(A17),MONTH(A17),1),交易记录!$A$6:$A$605,"<"&DATE(YEAR(A17),MONTH(A17)+1,1),交易记录!$C$6:$C$605,"买入",交易记录!$P$6:$P$605,"<>分红再投",交易记录!$P$6:$P$605,"<>其他",交易记录!$B$6:$B$605,"VOO")+SUMIFS(交易记录!$D$6:$D$605,交易记录!$A$6:$A$605,">="&DATE(YEAR(A17),MONTH(A17),1),交易记录!$A$6:$A$605,"<"&DATE(YEAR(A17),MONTH(A17)+1,1),交易记录!$C$6:$C$605,"买入",交易记录!$P$6:$P$605,"<>分红再投",交易记录!$P$6:$P$605,"<>其他",交易记录!$B$6:$B$605,"QQQM")+SUMIFS(交易记录!$E$6:$E$605,交易记录!$A$6:$A$605,">="&DATE(YEAR(A17),MONTH(A17),1),交易记录!$A$6:$A$605,"<"&DATE(YEAR(A17),MONTH(A17)+1,1),交易记录!$C$6:$C$605,"买入",交易记录!$P$6:$P$605,"<>分红再投",交易记录!$P$6:$P$605,"<>其他",交易记录!$B$6:$B$605,"VOO")+SUMIFS(交易记录!$E$6:$E$605,交易记录!$A$6:$A$605,">="&DATE(YEAR(A17),MONTH(A17),1),交易记录!$A$6:$A$605,"<"&DATE(YEAR(A17),MONTH(A17)+1,1),交易记录!$C$6:$C$605,"买入",交易记录!$P$6:$P$605,"<>分红再投",交易记录!$P$6:$P$605,"<>其他",交易记录!$B$6:$B$605,"QQQM") -> 0 | N17: =MAX(0,M17-$B$4) -> 0 | P17: =IF(O17="",N17,O17) -> 0 | Q17: =MAX(0,H17-P17) -> 5000 | R17: =IF(P17>H17+0.005,"实际加投超剩余预算，请核对",IF(H17=0,"预算用完：基础定投",IF(F17="","待补指数收盘／历史基准；先列基础额",IF(AND(B17>A17,M17=0),"核对观察日是否在实际交易前",IF(AND(O17<>"",ABS(O17-N17)>0.005),"已按手填额外支出扣预算",IF(M17=0,"已计算，尚未记录买入",IF(ABS(M17-J17)<0.01,"已按计划记录","实际定投与计划有差额"))))))) -> 待补指数收盘／历史基准；先列基础额
A18: =月度计划!A15 -> 46578 | E18: =IF(MAX($H$4,E17,D18)<=0,"",MAX($H$4,E17,D18,C18)) -> 7794.35 | F18: =IF(AND(ISNUMBER(B18),ISNUMBER(C18),C18>0,ISNUMBER(E18),E18>0),MAX(0,1-C18/E18),"") | G18: =IF(F18="","",IF(ROUND(F18,10)<0.1,$B$4,IF(ROUND(F18,10)<0.2,$B$4+250,$B$4+500))) | H18: =MAX(0,$E$4-SUM($P$9:P17)) -> 5000 | I18: =IF(G18="",0,MIN(MAX(0,G18-$B$4),H18)) -> 0 | J18: =$B$4+I18 -> 500 | K18: =J18*总览!$B$8 -> 450 | L18: =J18*总览!$B$9 -> 50 | M18: =SUMIFS(交易记录!$D$6:$D$605,交易记录!$A$6:$A$605,">="&DATE(YEAR(A18),MONTH(A18),1),交易记录!$A$6:$A$605,"<"&DATE(YEAR(A18),MONTH(A18)+1,1),交易记录!$C$6:$C$605,"买入",交易记录!$P$6:$P$605,"<>分红再投",交易记录!$P$6:$P$605,"<>其他",交易记录!$B$6:$B$605,"VOO")+SUMIFS(交易记录!$D$6:$D$605,交易记录!$A$6:$A$605,">="&DATE(YEAR(A18),MONTH(A18),1),交易记录!$A$6:$A$605,"<"&DATE(YEAR(A18),MONTH(A18)+1,1),交易记录!$C$6:$C$605,"买入",交易记录!$P$6:$P$605,"<>分红再投",交易记录!$P$6:$P$605,"<>其他",交易记录!$B$6:$B$605,"QQQM")+SUMIFS(交易记录!$E$6:$E$605,交易记录!$A$6:$A$605,">="&DATE(YEAR(A18),MONTH(A18),1),交易记录!$A$6:$A$605,"<"&DATE(YEAR(A18),MONTH(A18)+1,1),交易记录!$C$6:$C$605,"买入",交易记录!$P$6:$P$605,"<>分红再投",交易记录!$P$6:$P$605,"<>其他",交易记录!$B$6:$B$605,"VOO")+SUMIFS(交易记录!$E$6:$E$605,交易记录!$A$6:$A$605,">="&DATE(YEAR(A18),MONTH(A18),1),交易记录!$A$6:$A$605,"<"&DATE(YEAR(A18),MONTH(A18)+1,1),交易记录!$C$6:$C$605,"买入",交易记录!$P$6:$P$605,"<>分红再投",交易记录!$P$6:$P$605,"<>其他",交易记录!$B$6:$B$605,"QQQM") -> 0 | N18: =MAX(0,M18-$B$4) -> 0 | P18: =IF(O18="",N18,O18) -> 0 | Q18: =MAX(0,H18-P18) -> 5000 | R18: =IF(P18>H18+0.005,"实际加投超剩余预算，请核对",IF(H18=0,"预算用完：基础定投",IF(F18="","待补指数收盘／历史基准；先列基础额",IF(AND(B18>A18,M18=0),"核对观察日是否在实际交易前",IF(AND(O18<>"",ABS(O18-N18)>0.005),"已按手填额外支出扣预算",IF(M18=0,"已计算，尚未记录买入",IF(ABS(M18-J18)<0.01,"已按计划记录","实际定投与计划有差额"))))))) -> 待补指数收盘／历史基准；先列基础额
A19: =月度计划!A16 -> 46609 | E19: =IF(MAX($H$4,E18,D19)<=0,"",MAX($H$4,E18,D19,C19)) -> 7794.35 | F19: =IF(AND(ISNUMBER(B19),ISNUMBER(C19),C19>0,ISNUMBER(E19),E19>0),MAX(0,1-C19/E19),"") | G19: =IF(F19="","",IF(ROUND(F19,10)<0.1,$B$4,IF(ROUND(F19,10)<0.2,$B$4+250,$B$4+500))) | H19: =MAX(0,$E$4-SUM($P$9:P18)) -> 5000 | I19: =IF(G19="",0,MIN(MAX(0,G19-$B$4),H19)) -> 0 | J19: =$B$4+I19 -> 500 | K19: =J19*总览!$B$8 -> 450 | L19: =J19*总览!$B$9 -> 50 | M19: =SUMIFS(交易记录!$D$6:$D$605,交易记录!$A$6:$A$605,">="&DATE(YEAR(A19),MONTH(A19),1),交易记录!$A$6:$A$605,"<"&DATE(YEAR(A19),MONTH(A19)+1,1),交易记录!$C$6:$C$605,"买入",交易记录!$P$6:$P$605,"<>分红再投",交易记录!$P$6:$P$605,"<>其他",交易记录!$B$6:$B$605,"VOO")+SUMIFS(交易记录!$D$6:$D$605,交易记录!$A$6:$A$605,">="&DATE(YEAR(A19),MONTH(A19),1),交易记录!$A$6:$A$605,"<"&DATE(YEAR(A19),MONTH(A19)+1,1),交易记录!$C$6:$C$605,"买入",交易记录!$P$6:$P$605,"<>分红再投",交易记录!$P$6:$P$605,"<>其他",交易记录!$B$6:$B$605,"QQQM")+SUMIFS(交易记录!$E$6:$E$605,交易记录!$A$6:$A$605,">="&DATE(YEAR(A19),MONTH(A19),1),交易记录!$A$6:$A$605,"<"&DATE(YEAR(A19),MONTH(A19)+1,1),交易记录!$C$6:$C$605,"买入",交易记录!$P$6:$P$605,"<>分红再投",交易记录!$P$6:$P$605,"<>其他",交易记录!$B$6:$B$605,"VOO")+SUMIFS(交易记录!$E$6:$E$605,交易记录!$A$6:$A$605,">="&DATE(YEAR(A19),MONTH(A19),1),交易记录!$A$6:$A$605,"<"&DATE(YEAR(A19),MONTH(A19)+1,1),交易记录!$C$6:$C$605,"买入",交易记录!$P$6:$P$605,"<>分红再投",交易记录!$P$6:$P$605,"<>其他",交易记录!$B$6:$B$605,"QQQM") -> 0 | N19: =MAX(0,M19-$B$4) -> 0 | P19: =IF(O19="",N19,O19) -> 0 | Q19: =MAX(0,H19-P19) -> 5000 | R19: =IF(P19>H19+0.005,"实际加投超剩余预算，请核对",IF(H19=0,"预算用完：基础定投",IF(F19="","待补指数收盘／历史基准；先列基础额",IF(AND(B19>A19,M19=0),"核对观察日是否在实际交易前",IF(AND(O19<>"",ABS(O19-N19)>0.005),"已按手填额外支出扣预算",IF(M19=0,"已计算，尚未记录买入",IF(ABS(M19-J19)<0.01,"已按计划记录","实际定投与计划有差额"))))))) -> 待补指数收盘／历史基准；先列基础额
A20: =月度计划!A17 -> 46640 | E20: =IF(MAX($H$4,E19,D20)<=0,"",MAX($H$4,E19,D20,C20)) -> 7794.35 | F20: =IF(AND(ISNUMBER(B20),ISNUMBER(C20),C20>0,ISNUMBER(E20),E20>0),MAX(0,1-C20/E20),"") | G20: =IF(F20="","",IF(ROUND(F20,10)<0.1,$B$4,IF(ROUND(F20,10)<0.2,$B$4+250,$B$4+500))) | H20: =MAX(0,$E$4-SUM($P$9:P19)) -> 5000 | I20: =IF(G20="",0,MIN(MAX(0,G20-$B$4),H20)) -> 0 | J20: =$B$4+I20 -> 500 | K20: =J20*总览!$B$8 -> 450 | L20: =J20*总览!$B$9 -> 50 | M20: =SUMIFS(交易记录!$D$6:$D$605,交易记录!$A$6:$A$605,">="&DATE(YEAR(A20),MONTH(A20),1),交易记录!$A$6:$A$605,"<"&DATE(YEAR(A20),MONTH(A20)+1,1),交易记录!$C$6:$C$605,"买入",交易记录!$P$6:$P$605,"<>分红再投",交易记录!$P$6:$P$605,"<>其他",交易记录!$B$6:$B$605,"VOO")+SUMIFS(交易记录!$D$6:$D$605,交易记录!$A$6:$A$605,">="&DATE(YEAR(A20),MONTH(A20),1),交易记录!$A$6:$A$605,"<"&DATE(YEAR(A20),MONTH(A20)+1,1),交易记录!$C$6:$C$605,"买入",交易记录!$P$6:$P$605,"<>分红再投",交易记录!$P$6:$P$605,"<>其他",交易记录!$B$6:$B$605,"QQQM")+SUMIFS(交易记录!$E$6:$E$605,交易记录!$A$6:$A$605,">="&DATE(YEAR(A20),MONTH(A20),1),交易记录!$A$6:$A$605,"<"&DATE(YEAR(A20),MONTH(A20)+1,1),交易记录!$C$6:$C$605,"买入",交易记录!$P$6:$P$605,"<>分红再投",交易记录!$P$6:$P$605,"<>其他",交易记录!$B$6:$B$605,"VOO")+SUMIFS(交易记录!$E$6:$E$605,交易记录!$A$6:$A$605,">="&DATE(YEAR(A20),MONTH(A20),1),交易记录!$A$6:$A$605,"<"&DATE(YEAR(A20),MONTH(A20)+1,1),交易记录!$C$6:$C$605,"买入",交易记录!$P$6:$P$605,"<>分红再投",交易记录!$P$6:$P$605,"<>其他",交易记录!$B$6:$B$605,"QQQM") -> 0 | N20: =MAX(0,M20-$B$4) -> 0 | P20: =IF(O20="",N20,O20) -> 0 | Q20: =MAX(0,H20-P20) -> 5000 | R20: =IF(P20>H20+0.005,"实际加投超剩余预算，请核对",IF(H20=0,"预算用完：基础定投",IF(F20="","待补指数收盘／历史基准；先列基础额",IF(AND(B20>A20,M20=0),"核对观察日是否在实际交易前",IF(AND(O20<>"",ABS(O20-N20)>0.005),"已按手填额外支出扣预算",IF(M20=0,"已计算，尚未记录买入",IF(ABS(M20-J20)<0.01,"已按计划记录","实际定投与计划有差额"))))))) -> 待补指数收盘／历史基准；先列基础额
A21: =月度计划!A18 -> 46670 | E21: =IF(MAX($H$4,E20,D21)<=0,"",MAX($H$4,E20,D21,C21)) -> 7794.35 | F21: =IF(AND(ISNUMBER(B21),ISNUMBER(C21),C21>0,ISNUMBER(E21),E21>0),MAX(0,1-C21/E21),"") | G21: =IF(F21="","",IF(ROUND(F21,10)<0.1,$B$4,IF(ROUND(F21,10)<0.2,$B$4+250,$B$4+500))) | H21: =MAX(0,$E$4-SUM($P$9:P20)) -> 5000 | I21: =IF(G21="",0,MIN(MAX(0,G21-$B$4),H21)) -> 0 | J21: =$B$4+I21 -> 500 | K21: =J21*总览!$B$8 -> 450 | L21: =J21*总览!$B$9 -> 50 | M21: =SUMIFS(交易记录!$D$6:$D$605,交易记录!$A$6:$A$605,">="&DATE(YEAR(A21),MONTH(A21),1),交易记录!$A$6:$A$605,"<"&DATE(YEAR(A21),MONTH(A21)+1,1),交易记录!$C$6:$C$605,"买入",交易记录!$P$6:$P$605,"<>分红再投",交易记录!$P$6:$P$605,"<>其他",交易记录!$B$6:$B$605,"VOO")+SUMIFS(交易记录!$D$6:$D$605,交易记录!$A$6:$A$605,">="&DATE(YEAR(A21),MONTH(A21),1),交易记录!$A$6:$A$605,"<"&DATE(YEAR(A21),MONTH(A21)+1,1),交易记录!$C$6:$C$605,"买入",交易记录!$P$6:$P$605,"<>分红再投",交易记录!$P$6:$P$605,"<>其他",交易记录!$B$6:$B$605,"QQQM")+SUMIFS(交易记录!$E$6:$E$605,交易记录!$A$6:$A$605,">="&DATE(YEAR(A21),MONTH(A21),1),交易记录!$A$6:$A$605,"<"&DATE(YEAR(A21),MONTH(A21)+1,1),交易记录!$C$6:$C$605,"买入",交易记录!$P$6:$P$605,"<>分红再投",交易记录!$P$6:$P$605,"<>其他",交易记录!$B$6:$B$605,"VOO")+SUMIFS(交易记录!$E$6:$E$605,交易记录!$A$6:$A$605,">="&DATE(YEAR(A21),MONTH(A21),1),交易记录!$A$6:$A$605,"<"&DATE(YEAR(A21),MONTH(A21)+1,1),交易记录!$C$6:$C$605,"买入",交易记录!$P$6:$P$605,"<>分红再投",交易记录!$P$6:$P$605,"<>其他",交易记录!$B$6:$B$605,"QQQM") -> 0 | N21: =MAX(0,M21-$B$4) -> 0 | P21: =IF(O21="",N21,O21) -> 0 | Q21: =MAX(0,H21-P21) -> 5000 | R21: =IF(P21>H21+0.005,"实际加投超剩余预算，请核对",IF(H21=0,"预算用完：基础定投",IF(F21="","待补指数收盘／历史基准；先列基础额",IF(AND(B21>A21,M21=0),"核对观察日是否在实际交易前",IF(AND(O21<>"",ABS(O21-N21)>0.005),"已按手填额外支出扣预算",IF(M21=0,"已计算，尚未记录买入",IF(ABS(M21-J21)<0.01,"已按计划记录","实际定投与计划有差额"))))))) -> 待补指数收盘／历史基准；先列基础额
... A128: =月度计划!A125 -> 49928 | E128: =IF(MAX($H$4,E127,D128)<=0,"",MAX($H$4,E127,D128,C128)) -> 7794.35 | F128: =IF(AND(ISNUMBER(B128),ISNUMBER(C128),C128>0,ISNUMBER(E128),E128>0),MAX(0,1-C128/E128),"") | G128: =IF(F128="","",IF(ROUND(F128,10)<0.1,$B$4,IF(ROUND(F128,10)<0.2,$B$4+250,$B$4+500))) | H128: =MAX(0,$E$4-SUM($P$9:P127)) -> 5000 | I128: =IF(G128="",0,MIN(MAX(0,G128-$B$4),H128)) -> 0 | J128: =$B$4+I128 -> 500 | K128: =J128*总览!$B$8 -> 450 | L128: =J128*总览!$B$9 -> 50 | M128: =SUMIFS(交易记录!$D$6:$D$605,交易记录!$A$6:$A$605,">="&DATE(YEAR(A128),MONTH(A128),1),交易记录!$A$6:$A$605,"<"&DATE(YEAR(A128),MONTH(A128)+1,1),交易记录!$C$6:$C$605,"买入",交易记录!$P$6:$P$605,"<>分红再投",交易记录!$P$6:$P$605,"<>其他",交易记录!$B$6:$B$605,"VOO")+SUMIFS(交易记录!$D$6:$D$605,交易记录!$A$6:$A$605,">="&DATE(YEAR(A128),MONTH(A128),1),交易记录!$A$6:$A$605,"<"&DATE(YEAR(A128),MONTH(A128)+1,1),交易记录!$C$6:$C$605,"买入",交易记录!$P$6:$P$605,"<>分红再投",交易记录!$P$6:$P$605,"<>其他",交易记录!$B$6:$B$605,"QQQM")+SUMIFS(交易记录!$E$6:$E$605,交易记录!$A$6:$A$605,">="&DATE(YEAR(A128),MONTH(A128),1),交易记录!$A$6:$A$605,"<"&DATE(YEAR(A128),MONTH(A128)+1,1),交易记录!$C$6:$C$605,"买入",交易记录!$P$6:$P$605,"<>分红再投",交易记录!$P$6:$P$605,"<>其他",交易记录!$B$6:$B$605,"VOO")+SUMIFS(交易记录!$E$6:$E$605,交易记录!$A$6:$A$605,">="&DATE(YEAR(A128),MONTH(A128),1),交易记录!$A$6:$A$605,"<"&DATE(YEAR(A128),MONTH(A128)+1,1),交易记录!$C$6:$C$605,"买入",交易记录!$P$6:$P$605,"<>分红再投",交易记录!$P$6:$P$605,"<>其他",交易记录!$B$6:$B$605,"QQQM") -> 0 | N128: =MAX(0,M128-$B$4) -> 0 | P128: =IF(O128="",N128,O128) -> 0 | Q128: =MAX(0,H128-P128) -> 5000 | R128: =IF(P128>H128+0.005,"实际加投超剩余预算，请核对",IF(H128=0,"预算用完：基础定投",IF(F128="","待补指数收盘／历史基准；先列基础额",IF(AND(B128>A128,M128=0),"核对观察日是否在实际交易前",IF(AND(O128<>"",ABS(O128-N128)>0.005),"已按手填额外支出扣预算",IF(M128=0,"已计算，尚未记录买入",IF(ABS(M128-J128)<0.01,"已按计划记录","实际定投与计划有差额"))))))) -> 待补指数收盘／历史基准；先列基础额

Sheet 月度计划
A1: 月度计划
A3: 每月金额关联“回撤计划”，VOO 90%／QQQM 10%。指数资料未填时仅列基础500；实际买入含手续费，分红再投／其他仍显示在实际合计，请结合回撤表常规定投核对。
A5: 计划日期 | B5: 回撤计划总额 USD | C5: VOO计划 USD | D5: QQQM计划 USD | E5: SMH计划 USD | F5: VOO实际 USD | G5: QQQM实际 USD | H5: SMH实际 USD | I5: 实际合计 USD | J5: 实际－预算 USD | K5: 执行状态
A6: =DATE(2026,10,总览!$E$4) -> 46305 | B6: =回撤计划!J9 -> 500 | C6: =B6*总览!$B$8 -> 450 | D6: =B6*总览!$B$9 -> 50 | E6: =B6*总览!$B$10 -> 0 | F6: =SUMIFS(交易记录!$D$6:$D$605,交易记录!$A$6:$A$605,">="&DATE(YEAR(A6),MONTH(A6),1),交易记录!$A$6:$A$605,"<"&DATE(YEAR(A6),MONTH(A6)+1,1),交易记录!$B$6:$B$605,"VOO",交易记录!$C$6:$C$605,"买入")+SUMIFS(交易记录!$E$6:$E$605,交易记录!$A$6:$A$605,">="&DATE(YEAR(A6),MONTH(A6),1),交易记录!$A$6:$A$605,"<"&DATE(YEAR(A6),MONTH(A6)+1,1),交易记录!$B$6:$B$605,"VOO",交易记录!$C$6:$C$605,"买入") -> 0 | G6: =SUMIFS(交易记录!$D$6:$D$605,交易记录!$A$6:$A$605,">="&DATE(YEAR(A6),MONTH(A6),1),交易记录!$A$6:$A$605,"<"&DATE(YEAR(A6),MONTH(A6)+1,1),交易记录!$B$6:$B$605,"QQQM",交易记录!$C$6:$C$605,"买入")+SUMIFS(交易记录!$E$6:$E$605,交易记录!$A$6:$A$605,">="&DATE(YEAR(A6),MONTH(A6),1),交易记录!$A$6:$A$605,"<"&DATE(YEAR(A6),MONTH(A6)+1,1),交易记录!$B$6:$B$605,"QQQM",交易记录!$C$6:$C$605,"买入") -> 0 | H6: =SUMIFS(交易记录!$D$6:$D$605,交易记录!$A$6:$A$605,">="&DATE(YEAR(A6),MONTH(A6),1),交易记录!$A$6:$A$605,"<"&DATE(YEAR(A6),MONTH(A6)+1,1),交易记录!$B$6:$B$605,"SMH",交易记录!$C$6:$C$605,"买入")+SUMIFS(交易记录!$E$6:$E$605,交易记录!$A$6:$A$605,">="&DATE(YEAR(A6),MONTH(A6),1),交易记录!$A$6:$A$605,"<"&DATE(YEAR(A6),MONTH(A6)+1,1),交易记录!$B$6:$B$605,"SMH",交易记录!$C$6:$C$605,"买入") -> 0 | I6: =SUM(F6:H6) -> 0 | J6: =IF(I6=0,"",I6-B6) | K6: =IF(I6=0,"尚未记录买入",IF(ABS(J6)<0.01,"已记录预算金额","已记录，金额有差额")) -> 尚未记录买入
A7: =DATE(2026,11,总览!$E$4) -> 46336 | B7: =回撤计划!J10 -> 500 | C7: =B7*总览!$B$8 -> 450 | D7: =B7*总览!$B$9 -> 50 | E7: =B7*总览!$B$10 -> 0 | F7: =SUMIFS(交易记录!$D$6:$D$605,交易记录!$A$6:$A$605,">="&DATE(YEAR(A7),MONTH(A7),1),交易记录!$A$6:$A$605,"<"&DATE(YEAR(A7),MONTH(A7)+1,1),交易记录!$B$6:$B$605,"VOO",交易记录!$C$6:$C$605,"买入")+SUMIFS(交易记录!$E$6:$E$605,交易记录!$A$6:$A$605,">="&DATE(YEAR(A7),MONTH(A7),1),交易记录!$A$6:$A$605,"<"&DATE(YEAR(A7),MONTH(A7)+1,1),交易记录!$B$6:$B$605,"VOO",交易记录!$C$6:$C$605,"买入") -> 0 | G7: =SUMIFS(交易记录!$D$6:$D$605,交易记录!$A$6:$A$605,">="&DATE(YEAR(A7),MONTH(A7),1),交易记录!$A$6:$A$605,"<"&DATE(YEAR(A7),MONTH(A7)+1,1),交易记录!$B$6:$B$605,"QQQM",交易记录!$C$6:$C$605,"买入")+SUMIFS(交易记录!$E$6:$E$605,交易记录!$A$6:$A$605,">="&DATE(YEAR(A7),MONTH(A7),1),交易记录!$A$6:$A$605,"<"&DATE(YEAR(A7),MONTH(A7)+1,1),交易记录!$B$6:$B$605,"QQQM",交易记录!$C$6:$C$605,"买入") -> 0 | H7: =SUMIFS(交易记录!$D$6:$D$605,交易记录!$A$6:$A$605,">="&DATE(YEAR(A7),MONTH(A7),1),交易记录!$A$6:$A$605,"<"&DATE(YEAR(A7),MONTH(A7)+1,1),交易记录!$B$6:$B$605,"SMH",交易记录!$C$6:$C$605,"买入")+SUMIFS(交易记录!$E$6:$E$605,交易记录!$A$6:$A$605,">="&DATE(YEAR(A7),MONTH(A7),1),交易记录!$A$6:$A$605,"<"&DATE(YEAR(A7),MONTH(A7)+1,1),交易记录!$B$6:$B$605,"SMH",交易记录!$C$6:$C$605,"买入") -> 0 | I7: =SUM(F7:H7) -> 0 | J7: =IF(I7=0,"",I7-B7) | K7: =IF(I7=0,"尚未记录买入",IF(ABS(J7)<0.01,"已记录预算金额","已记录，金额有差额")) -> 尚未记录买入
A8: =DATE(2026,12,总览!$E$4) -> 46366 | B8: =回撤计划!J11 -> 500 | C8: =B8*总览!$B$8 -> 450 | D8: =B8*总览!$B$9 -> 50 | E8: =B8*总览!$B$10 -> 0 | F8: =SUMIFS(交易记录!$D$6:$D$605,交易记录!$A$6:$A$605,">="&DATE(YEAR(A8),MONTH(A8),1),交易记录!$A$6:$A$605,"<"&DATE(YEAR(A8),MONTH(A8)+1,1),交易记录!$B$6:$B$605,"VOO",交易记录!$C$6:$C$605,"买入")+SUMIFS(交易记录!$E$6:$E$605,交易记录!$A$6:$A$605,">="&DATE(YEAR(A8),MONTH(A8),1),交易记录!$A$6:$A$605,"<"&DATE(YEAR(A8),MONTH(A8)+1,1),交易记录!$B$6:$B$605,"VOO",交易记录!$C$6:$C$605,"买入") -> 0 | G8: =SUMIFS(交易记录!$D$6:$D$605,交易记录!$A$6:$A$605,">="&DATE(YEAR(A8),MONTH(A8),1),交易记录!$A$6:$A$605,"<"&DATE(YEAR(A8),MONTH(A8)+1,1),交易记录!$B$6:$B$605,"QQQM",交易记录!$C$6:$C$605,"买入")+SUMIFS(交易记录!$E$6:$E$605,交易记录!$A$6:$A$605,">="&DATE(YEAR(A8),MONTH(A8),1),交易记录!$A$6:$A$605,"<"&DATE(YEAR(A8),MONTH(A8)+1,1),交易记录!$B$6:$B$605,"QQQM",交易记录!$C$6:$C$605,"买入") -> 0 | H8: =SUMIFS(交易记录!$D$6:$D$605,交易记录!$A$6:$A$605,">="&DATE(YEAR(A8),MONTH(A8),1),交易记录!$A$6:$A$605,"<"&DATE(YEAR(A8),MONTH(A8)+1,1),交易记录!$B$6:$B$605,"SMH",交易记录!$C$6:$C$605,"买入")+SUMIFS(交易记录!$E$6:$E$605,交易记录!$A$6:$A$605,">="&DATE(YEAR(A8),MONTH(A8),1),交易记录!$A$6:$A$605,"<"&DATE(YEAR(A8),MONTH(A8)+1,1),交易记录!$B$6:$B$605,"SMH",交易记录!$C$6:$C$605,"买入") -> 0 | I8: =SUM(F8:H8) -> 0 | J8: =IF(I8=0,"",I8-B8) | K8: =IF(I8=0,"尚未记录买入",IF(ABS(J8)<0.01,"已记录预算金额","已记录，金额有差额")) -> 尚未记录买入
A9: =DATE(2027,1,总览!$E$4) -> 46397 | B9: =回撤计划!J12 -> 500 | C9: =B9*总览!$B$8 -> 450 | D9: =B9*总览!$B$9 -> 50 | E9: =B9*总览!$B$10 -> 0 | F9: =SUMIFS(交易记录!$D$6:$D$605,交易记录!$A$6:$A$605,">="&DATE(YEAR(A9),MONTH(A9),1),交易记录!$A$6:$A$605,"<"&DATE(YEAR(A9),MONTH(A9)+1,1),交易记录!$B$6:$B$605,"VOO",交易记录!$C$6:$C$605,"买入")+SUMIFS(交易记录!$E$6:$E$605,交易记录!$A$6:$A$605,">="&DATE(YEAR(A9),MONTH(A9),1),交易记录!$A$6:$A$605,"<"&DATE(YEAR(A9),MONTH(A9)+1,1),交易记录!$B$6:$B$605,"VOO",交易记录!$C$6:$C$605,"买入") -> 0 | G9: =SUMIFS(交易记录!$D$6:$D$605,交易记录!$A$6:$A$605,">="&DATE(YEAR(A9),MONTH(A9),1),交易记录!$A$6:$A$605,"<"&DATE(YEAR(A9),MONTH(A9)+1,1),交易记录!$B$6:$B$605,"QQQM",交易记录!$C$6:$C$605,"买入")+SUMIFS(交易记录!$E$6:$E$605,交易记录!$A$6:$A$605,">="&DATE(YEAR(A9),MONTH(A9),1),交易记录!$A$6:$A$605,"<"&DATE(YEAR(A9),MONTH(A9)+1,1),交易记录!$B$6:$B$605,"QQQM",交易记录!$C$6:$C$605,"买入") -> 0 | H9: =SUMIFS(交易记录!$D$6:$D$605,交易记录!$A$6:$A$605,">="&DATE(YEAR(A9),MONTH(A9),1),交易记录!$A$6:$A$605,"<"&DATE(YEAR(A9),MONTH(A9)+1,1),交易记录!$B$6:$B$605,"SMH",交易记录!$C$6:$C$605,"买入")+SUMIFS(交易记录!$E$6:$E$605,交易记录!$A$6:$A$605,">="&DATE(YEAR(A9),MONTH(A9),1),交易记录!$A$6:$A$605,"<"&DATE(YEAR(A9),MONTH(A9)+1,1),交易记录!$B$6:$B$605,"SMH",交易记录!$C$6:$C$605,"买入") -> 0 | I9: =SUM(F9:H9) -> 0 | J9: =IF(I9=0,"",I9-B9) | K9: =IF(I9=0,"尚未记录买入",IF(ABS(J9)<0.01,"已记录预算金额","已记录，金额有差额")) -> 尚未记录买入
A10: =DATE(2027,2,总览!$E$4) -> 46428 | B10: =回撤计划!J13 -> 500 | C10: =B10*总览!$B$8 -> 450 | D10: =B10*总览!$B$9 -> 50 | E10: =B10*总览!$B$10 -> 0 | F10: =SUMIFS(交易记录!$D$6:$D$605,交易记录!$A$6:$A$605,">="&DATE(YEAR(A10),MONTH(A10),1),交易记录!$A$6:$A$605,"<"&DATE(YEAR(A10),MONTH(A10)+1,1),交易记录!$B$6:$B$605,"VOO",交易记录!$C$6:$C$605,"买入")+SUMIFS(交易记录!$E$6:$E$605,交易记录!$A$6:$A$605,">="&DATE(YEAR(A10),MONTH(A10),1),交易记录!$A$6:$A$605,"<"&DATE(YEAR(A10),MONTH(A10)+1,1),交易记录!$B$6:$B$605,"VOO",交易记录!$C$6:$C$605,"买入") -> 0 | G10: =SUMIFS(交易记录!$D$6:$D$605,交易记录!$A$6:$A$605,">="&DATE(YEAR(A10),MONTH(A10),1),交易记录!$A$6:$A$605,"<"&DATE(YEAR(A10),MONTH(A10)+1,1),交易记录!$B$6:$B$605,"QQQM",交易记录!$C$6:$C$605,"买入")+SUMIFS(交易记录!$E$6:$E$605,交易记录!$A$6:$A$605,">="&DATE(YEAR(A10),MONTH(A10),1),交易记录!$A$6:$A$605,"<"&DATE(YEAR(A10),MONTH(A10)+1,1),交易记录!$B$6:$B$605,"QQQM",交易记录!$C$6:$C$605,"买入") -> 0 | H10: =SUMIFS(交易记录!$D$6:$D$605,交易记录!$A$6:$A$605,">="&DATE(YEAR(A10),MONTH(A10),1),交易记录!$A$6:$A$605,"<"&DATE(YEAR(A10),MONTH(A10)+1,1),交易记录!$B$6:$B$605,"SMH",交易记录!$C$6:$C$605,"买入")+SUMIFS(交易记录!$E$6:$E$605,交易记录!$A$6:$A$605,">="&DATE(YEAR(A10),MONTH(A10),1),交易记录!$A$6:$A$605,"<"&DATE(YEAR(A10),MONTH(A10)+1,1),交易记录!$B$6:$B$605,"SMH",交易记录!$C$6:$C$605,"买入") -> 0 | I10: =SUM(F10:H10) -> 0 | J10: =IF(I10=0,"",I10-B10) | K10: =IF(I10=0,"尚未记录买入",IF(ABS(J10)<0.01,"已记录预算金额","已记录，金额有差额")) -> 尚未记录买入
A11: =DATE(2027,3,总览!$E$4) -> 46456 | B11: =回撤计划!J14 -> 500 | C11: =B11*总览!$B$8 -> 450 | D11: =B11*总览!$B$9 -> 50 | E11: =B11*总览!$B$10 -> 0 | F11: =SUMIFS(交易记录!$D$6:$D$605,交易记录!$A$6:$A$605,">="&DATE(YEAR(A11),MONTH(A11),1),交易记录!$A$6:$A$605,"<"&DATE(YEAR(A11),MONTH(A11)+1,1),交易记录!$B$6:$B$605,"VOO",交易记录!$C$6:$C$605,"买入")+SUMIFS(交易记录!$E$6:$E$605,交易记录!$A$6:$A$605,">="&DATE(YEAR(A11),MONTH(A11),1),交易记录!$A$6:$A$605,"<"&DATE(YEAR(A11),MONTH(A11)+1,1),交易记录!$B$6:$B$605,"VOO",交易记录!$C$6:$C$605,"买入") -> 0 | G11: =SUMIFS(交易记录!$D$6:$D$605,交易记录!$A$6:$A$605,">="&DATE(YEAR(A11),MONTH(A11),1),交易记录!$A$6:$A$605,"<"&DATE(YEAR(A11),MONTH(A11)+1,1),交易记录!$B$6:$B$605,"QQQM",交易记录!$C$6:$C$605,"买入")+SUMIFS(交易记录!$E$6:$E$605,交易记录!$A$6:$A$605,">="&DATE(YEAR(A11),MONTH(A11),1),交易记录!$A$6:$A$605,"<"&DATE(YEAR(A11),MONTH(A11)+1,1),交易记录!$B$6:$B$605,"QQQM",交易记录!$C$6:$C$605,"买入") -> 0 | H11: =SUMIFS(交易记录!$D$6:$D$605,交易记录!$A$6:$A$605,">="&DATE(YEAR(A11),MONTH(A11),1),交易记录!$A$6:$A$605,"<"&DATE(YEAR(A11),MONTH(A11)+1,1),交易记录!$B$6:$B$605,"SMH",交易记录!$C$6:$C$605,"买入")+SUMIFS(交易记录!$E$6:$E$605,交易记录!$A$6:$A$605,">="&DATE(YEAR(A11),MONTH(A11),1),交易记录!$A$6:$A$605,"<"&DATE(YEAR(A11),MONTH(A11)+1,1),交易记录!$B$6:$B$605,"SMH",交易记录!$C$6:$C$605,"买入") -> 0 | I11: =SUM(F11:H11) -> 0 | J11: =IF(I11=0,"",I11-B11) | K11: =IF(I11=0,"尚未记录买入",IF(ABS(J11)<0.01,"已记录预算金额","已记录，金额有差额")) -> 尚未记录买入
A12: =DATE(2027,4,总览!$E$4) -> 46487 | B12: =回撤计划!J15 -> 500 | C12: =B12*总览!$B$8 -> 450 | D12: =B12*总览!$B$9 -> 50 | E12: =B12*总览!$B$10 -> 0 | F12: =SUMIFS(交易记录!$D$6:$D$605,交易记录!$A$6:$A$605,">="&DATE(YEAR(A12),MONTH(A12),1),交易记录!$A$6:$A$605,"<"&DATE(YEAR(A12),MONTH(A12)+1,1),交易记录!$B$6:$B$605,"VOO",交易记录!$C$6:$C$605,"买入")+SUMIFS(交易记录!$E$6:$E$605,交易记录!$A$6:$A$605,">="&DATE(YEAR(A12),MONTH(A12),1),交易记录!$A$6:$A$605,"<"&DATE(YEAR(A12),MONTH(A12)+1,1),交易记录!$B$6:$B$605,"VOO",交易记录!$C$6:$C$605,"买入") -> 0 | G12: =SUMIFS(交易记录!$D$6:$D$605,交易记录!$A$6:$A$605,">="&DATE(YEAR(A12),MONTH(A12),1),交易记录!$A$6:$A$605,"<"&DATE(YEAR(A12),MONTH(A12)+1,1),交易记录!$B$6:$B$605,"QQQM",交易记录!$C$6:$C$605,"买入")+SUMIFS(交易记录!$E$6:$E$605,交易记录!$A$6:$A$605,">="&DATE(YEAR(A12),MONTH(A12),1),交易记录!$A$6:$A$605,"<"&DATE(YEAR(A12),MONTH(A12)+1,1),交易记录!$B$6:$B$605,"QQQM",交易记录!$C$6:$C$605,"买入") -> 0 | H12: =SUMIFS(交易记录!$D$6:$D$605,交易记录!$A$6:$A$605,">="&DATE(YEAR(A12),MONTH(A12),1),交易记录!$A$6:$A$605,"<"&DATE(YEAR(A12),MONTH(A12)+1,1),交易记录!$B$6:$B$605,"SMH",交易记录!$C$6:$C$605,"买入")+SUMIFS(交易记录!$E$6:$E$605,交易记录!$A$6:$A$605,">="&DATE(YEAR(A12),MONTH(A12),1),交易记录!$A$6:$A$605,"<"&DATE(YEAR(A12),MONTH(A12)+1,1),交易记录!$B$6:$B$605,"SMH",交易记录!$C$6:$C$605,"买入") -> 0 | I12: =SUM(F12:H12) -> 0 | J12: =IF(I12=0,"",I12-B12) | K12: =IF(I12=0,"尚未记录买入",IF(ABS(J12)<0.01,"已记录预算金额","已记录，金额有差额")) -> 尚未记录买入
A13: =DATE(2027,5,总览!$E$4) -> 46517 | B13: =回撤计划!J16 -> 500 | C13: =B13*总览!$B$8 -> 450 | D13: =B13*总览!$B$9 -> 50 | E13: =B13*总览!$B$10 -> 0 | F13: =SUMIFS(交易记录!$D$6:$D$605,交易记录!$A$6:$A$605,">="&DATE(YEAR(A13),MONTH(A13),1),交易记录!$A$6:$A$605,"<"&DATE(YEAR(A13),MONTH(A13)+1,1),交易记录!$B$6:$B$605,"VOO",交易记录!$C$6:$C$605,"买入")+SUMIFS(交易记录!$E$6:$E$605,交易记录!$A$6:$A$605,">="&DATE(YEAR(A13),MONTH(A13),1),交易记录!$A$6:$A$605,"<"&DATE(YEAR(A13),MONTH(A13)+1,1),交易记录!$B$6:$B$605,"VOO",交易记录!$C$6:$C$605,"买入") -> 0 | G13: =SUMIFS(交易记录!$D$6:$D$605,交易记录!$A$6:$A$605,">="&DATE(YEAR(A13),MONTH(A13),1),交易记录!$A$6:$A$605,"<"&DATE(YEAR(A13),MONTH(A13)+1,1),交易记录!$B$6:$B$605,"QQQM",交易记录!$C$6:$C$605,"买入")+SUMIFS(交易记录!$E$6:$E$605,交易记录!$A$6:$A$605,">="&DATE(YEAR(A13),MONTH(A13),1),交易记录!$A$6:$A$605,"<"&DATE(YEAR(A13),MONTH(A13)+1,1),交易记录!$B$6:$B$605,"QQQM",交易记录!$C$6:$C$605,"买入") -> 0 | H13: =SUMIFS(交易记录!$D$6:$D$605,交易记录!$A$6:$A$605,">="&DATE(YEAR(A13),MONTH(A13),1),交易记录!$A$6:$A$605,"<"&DATE(YEAR(A13),MONTH(A13)+1,1),交易记录!$B$6:$B$605,"SMH",交易记录!$C$6:$C$605,"买入")+SUMIFS(交易记录!$E$6:$E$605,交易记录!$A$6:$A$605,">="&DATE(YEAR(A13),MONTH(A13),1),交易记录!$A$6:$A$605,"<"&DATE(YEAR(A13),MONTH(A13)+1,1),交易记录!$B$6:$B$605,"SMH",交易记录!$C$6:$C$605,"买入") -> 0 | I13: =SUM(F13:H13) -> 0 | J13: =IF(I13=0,"",I13-B13) | K13: =IF(I13=0,"尚未记录买入",IF(ABS(J13)<0.01,"已记录预算金额","已记录，金额有差额")) -> 尚未记录买入
A14: =DATE(2027,6,总览!$E$4) -> 46548 | B14: =回撤计划!J17 -> 500 | C14: =B14*总览!$B$8 -> 450 | D14: =B14*总览!$B$9 -> 50 | E14: =B14*总览!$B$10 -> 0 | F14: =SUMIFS(交易记录!$D$6:$D$605,交易记录!$A$6:$A$605,">="&DATE(YEAR(A14),MONTH(A14),1),交易记录!$A$6:$A$605,"<"&DATE(YEAR(A14),MONTH(A14)+1,1),交易记录!$B$6:$B$605,"VOO",交易记录!$C$6:$C$605,"买入")+SUMIFS(交易记录!$E$6:$E$605,交易记录!$A$6:$A$605,">="&DATE(YEAR(A14),MONTH(A14),1),交易记录!$A$6:$A$605,"<"&DATE(YEAR(A14),MONTH(A14)+1,1),交易记录!$B$6:$B$605,"VOO",交易记录!$C$6:$C$605,"买入") -> 0 | G14: =SUMIFS(交易记录!$D$6:$D$605,交易记录!$A$6:$A$605,">="&DATE(YEAR(A14),MONTH(A14),1),交易记录!$A$6:$A$605,"<"&DATE(YEAR(A14),MONTH(A14)+1,1),交易记录!$B$6:$B$605,"QQQM",交易记录!$C$6:$C$605,"买入")+SUMIFS(交易记录!$E$6:$E$605,交易记录!$A$6:$A$605,">="&DATE(YEAR(A14),MONTH(A14),1),交易记录!$A$6:$A$605,"<"&DATE(YEAR(A14),MONTH(A14)+1,1),交易记录!$B$6:$B$605,"QQQM",交易记录!$C$6:$C$605,"买入") -> 0 | H14: =SUMIFS(交易记录!$D$6:$D$605,交易记录!$A$6:$A$605,">="&DATE(YEAR(A14),MONTH(A14),1),交易记录!$A$6:$A$605,"<"&DATE(YEAR(A14),MONTH(A14)+1,1),交易记录!$B$6:$B$605,"SMH",交易记录!$C$6:$C$605,"买入")+SUMIFS(交易记录!$E$6:$E$605,交易记录!$A$6:$A$605,">="&DATE(YEAR(A14),MONTH(A14),1),交易记录!$A$6:$A$605,"<"&DATE(YEAR(A14),MONTH(A14)+1,1),交易记录!$B$6:$B$605,"SMH",交易记录!$C$6:$C$605,"买入") -> 0 | I14: =SUM(F14:H14) -> 0 | J14: =IF(I14=0,"",I14-B14) | K14: =IF(I14=0,"尚未记录买入",IF(ABS(J14)<0.01,"已记录预算金额","已记录，金额有差额")) -> 尚未记录买入
A15: =DATE(2027,7,总览!$E$4) -> 46578 | B15: =回撤计划!J18 -> 500 | C15: =B15*总览!$B$8 -> 450 | D15: =B15*总览!$B$9 -> 50 | E15: =B15*总览!$B$10 -> 0 | F15: =SUMIFS(交易记录!$D$6:$D$605,交易记录!$A$6:$A$605,">="&DATE(YEAR(A15),MONTH(A15),1),交易记录!$A$6:$A$605,"<"&DATE(YEAR(A15),MONTH(A15)+1,1),交易记录!$B$6:$B$605,"VOO",交易记录!$C$6:$C$605,"买入")+SUMIFS(交易记录!$E$6:$E$605,交易记录!$A$6:$A$605,">="&DATE(YEAR(A15),MONTH(A15),1),交易记录!$A$6:$A$605,"<"&DATE(YEAR(A15),MONTH(A15)+1,1),交易记录!$B$6:$B$605,"VOO",交易记录!$C$6:$C$605,"买入") -> 0 | G15: =SUMIFS(交易记录!$D$6:$D$605,交易记录!$A$6:$A$605,">="&DATE(YEAR(A15),MONTH(A15),1),交易记录!$A$6:$A$605,"<"&DATE(YEAR(A15),MONTH(A15)+1,1),交易记录!$B$6:$B$605,"QQQM",交易记录!$C$6:$C$605,"买入")+SUMIFS(交易记录!$E$6:$E$605,交易记录!$A$6:$A$605,">="&DATE(YEAR(A15),MONTH(A15),1),交易记录!$A$6:$A$605,"<"&DATE(YEAR(A15),MONTH(A15)+1,1),交易记录!$B$6:$B$605,"QQQM",交易记录!$C$6:$C$605,"买入") -> 0 | H15: =SUMIFS(交易记录!$D$6:$D$605,交易记录!$A$6:$A$605,">="&DATE(YEAR(A15),MONTH(A15),1),交易记录!$A$6:$A$605,"<"&DATE(YEAR(A15),MONTH(A15)+1,1),交易记录!$B$6:$B$605,"SMH",交易记录!$C$6:$C$605,"买入")+SUMIFS(交易记录!$E$6:$E$605,交易记录!$A$6:$A$605,">="&DATE(YEAR(A15),MONTH(A15),1),交易记录!$A$6:$A$605,"<"&DATE(YEAR(A15),MONTH(A15)+1,1),交易记录!$B$6:$B$605,"SMH",交易记录!$C$6:$C$605,"买入") -> 0 | I15: =SUM(F15:H15) -> 0 | J15: =IF(I15=0,"",I15-B15) | K15: =IF(I15=0,"尚未记录买入",IF(ABS(J15)<0.01,"已记录预算金额","已记录，金额有差额")) -> 尚未记录买入
A16: =DATE(2027,8,总览!$E$4) -> 46609 | B16: =回撤计划!J19 -> 500 | C16: =B16*总览!$B$8 -> 450 | D16: =B16*总览!$B$9 -> 50 | E16: =B16*总览!$B$10 -> 0 | F16: =SUMIFS(交易记录!$D$6:$D$605,交易记录!$A$6:$A$605,">="&DATE(YEAR(A16),MONTH(A16),1),交易记录!$A$6:$A$605,"<"&DATE(YEAR(A16),MONTH(A16)+1,1),交易记录!$B$6:$B$605,"VOO",交易记录!$C$6:$C$605,"买入")+SUMIFS(交易记录!$E$6:$E$605,交易记录!$A$6:$A$605,">="&DATE(YEAR(A16),MONTH(A16),1),交易记录!$A$6:$A$605,"<"&DATE(YEAR(A16),MONTH(A16)+1,1),交易记录!$B$6:$B$605,"VOO",交易记录!$C$6:$C$605,"买入") -> 0 | G16: =SUMIFS(交易记录!$D$6:$D$605,交易记录!$A$6:$A$605,">="&DATE(YEAR(A16),MONTH(A16),1),交易记录!$A$6:$A$605,"<"&DATE(YEAR(A16),MONTH(A16)+1,1),交易记录!$B$6:$B$605,"QQQM",交易记录!$C$6:$C$605,"买入")+SUMIFS(交易记录!$E$6:$E$605,交易记录!$A$6:$A$605,">="&DATE(YEAR(A16),MONTH(A16),1),交易记录!$A$6:$A$605,"<"&DATE(YEAR(A16),MONTH(A16)+1,1),交易记录!$B$6:$B$605,"QQQM",交易记录!$C$6:$C$605,"买入") -> 0 | H16: =SUMIFS(交易记录!$D$6:$D$605,交易记录!$A$6:$A$605,">="&DATE(YEAR(A16),MONTH(A16),1),交易记录!$A$6:$A$605,"<"&DATE(YEAR(A16),MONTH(A16)+1,1),交易记录!$B$6:$B$605,"SMH",交易记录!$C$6:$C$605,"买入")+SUMIFS(交易记录!$E$6:$E$605,交易记录!$A$6:$A$605,">="&DATE(YEAR(A16),MONTH(A16),1),交易记录!$A$6:$A$605,"<"&DATE(YEAR(A16),MONTH(A16)+1,1),交易记录!$B$6:$B$605,"SMH",交易记录!$C$6:$C$605,"买入") -> 0 | I16: =SUM(F16:H16) -> 0 | J16: =IF(I16=0,"",I16-B16) | K16: =IF(I16=0,"尚未记录买入",IF(ABS(J16)<0.01,"已记录预算金额","已记录，金额有差额")) -> 尚未记录买入
A17: =DATE(2027,9,总览!$E$4) -> 46640 | B17: =回撤计划!J20 -> 500 | C17: =B17*总览!$B$8 -> 450 | D17: =B17*总览!$B$9 -> 50 | E17: =B17*总览!$B$10 -> 0 | F17: =SUMIFS(交易记录!$D$6:$D$605,交易记录!$A$6:$A$605,">="&DATE(YEAR(A17),MONTH(A17),1),交易记录!$A$6:$A$605,"<"&DATE(YEAR(A17),MONTH(A17)+1,1),交易记录!$B$6:$B$605,"VOO",交易记录!$C$6:$C$605,"买入")+SUMIFS(交易记录!$E$6:$E$605,交易记录!$A$6:$A$605,">="&DATE(YEAR(A17),MONTH(A17),1),交易记录!$A$6:$A$605,"<"&DATE(YEAR(A17),MONTH(A17)+1,1),交易记录!$B$6:$B$605,"VOO",交易记录!$C$6:$C$605,"买入") -> 0 | G17: =SUMIFS(交易记录!$D$6:$D$605,交易记录!$A$6:$A$605,">="&DATE(YEAR(A17),MONTH(A17),1),交易记录!$A$6:$A$605,"<"&DATE(YEAR(A17),MONTH(A17)+1,1),交易记录!$B$6:$B$605,"QQQM",交易记录!$C$6:$C$605,"买入")+SUMIFS(交易记录!$E$6:$E$605,交易记录!$A$6:$A$605,">="&DATE(YEAR(A17),MONTH(A17),1),交易记录!$A$6:$A$605,"<"&DATE(YEAR(A17),MONTH(A17)+1,1),交易记录!$B$6:$B$605,"QQQM",交易记录!$C$6:$C$605,"买入") -> 0 | H17: =SUMIFS(交易记录!$D$6:$D$605,交易记录!$A$6:$A$605,">="&DATE(YEAR(A17),MONTH(A17),1),交易记录!$A$6:$A$605,"<"&DATE(YEAR(A17),MONTH(A17)+1,1),交易记录!$B$6:$B$605,"SMH",交易记录!$C$6:$C$605,"买入")+SUMIFS(交易记录!$E$6:$E$605,交易记录!$A$6:$A$605,">="&DATE(YEAR(A17),MONTH(A17),1),交易记录!$A$6:$A$605,"<"&DATE(YEAR(A17),MONTH(A17)+1,1),交易记录!$B$6:$B$605,"SMH",交易记录!$C$6:$C$605,"买入") -> 0 | I17: =SUM(F17:H17) -> 0 | J17: =IF(I17=0,"",I17-B17) | K17: =IF(I17=0,"尚未记录买入",IF(ABS(J17)<0.01,"已记录预算金额","已记录，金额有差额")) -> 尚未记录买入
A18: =DATE(2027,10,总览!$E$4) -> 46670 | B18: =回撤计划!J21 -> 500 | C18: =B18*总览!$B$8 -> 450 | D18: =B18*总览!$B$9 -> 50 | E18: =B18*总览!$B$10 -> 0 | F18: =SUMIFS(交易记录!$D$6:$D$605,交易记录!$A$6:$A$605,">="&DATE(YEAR(A18),MONTH(A18),1),交易记录!$A$6:$A$605,"<"&DATE(YEAR(A18),MONTH(A18)+1,1),交易记录!$B$6:$B$605,"VOO",交易记录!$C$6:$C$605,"买入")+SUMIFS(交易记录!$E$6:$E$605,交易记录!$A$6:$A$605,">="&DATE(YEAR(A18),MONTH(A18),1),交易记录!$A$6:$A$605,"<"&DATE(YEAR(A18),MONTH(A18)+1,1),交易记录!$B$6:$B$605,"VOO",交易记录!$C$6:$C$605,"买入") -> 0 | G18: =SUMIFS(交易记录!$D$6:$D$605,交易记录!$A$6:$A$605,">="&DATE(YEAR(A18),MONTH(A18),1),交易记录!$A$6:$A$605,"<"&DATE(YEAR(A18),MONTH(A18)+1,1),交易记录!$B$6:$B$605,"QQQM",交易记录!$C$6:$C$605,"买入")+SUMIFS(交易记录!$E$6:$E$605,交易记录!$A$6:$A$605,">="&DATE(YEAR(A18),MONTH(A18),1),交易记录!$A$6:$A$605,"<"&DATE(YEAR(A18),MONTH(A18)+1,1),交易记录!$B$6:$B$605,"QQQM",交易记录!$C$6:$C$605,"买入") -> 0 | H18: =SUMIFS(交易记录!$D$6:$D$605,交易记录!$A$6:$A$605,">="&DATE(YEAR(A18),MONTH(A18),1),交易记录!$A$6:$A$605,"<"&DATE(YEAR(A18),MONTH(A18)+1,1),交易记录!$B$6:$B$605,"SMH",交易记录!$C$6:$C$605,"买入")+SUMIFS(交易记录!$E$6:$E$605,交易记录!$A$6:$A$605,">="&DATE(YEAR(A18),MONTH(A18),1),交易记录!$A$6:$A$605,"<"&DATE(YEAR(A18),MONTH(A18)+1,1),交易记录!$B$6:$B$605,"SMH",交易记录!$C$6:$C$605,"买入") -> 0 | I18: =SUM(F18:H18) -> 0 | J18: =IF(I18=0,"",I18-B18) | K18: =IF(I18=0,"尚未记录买入",IF(ABS(J18)<0.01,"已记录预算金额","已记录，金额有差额")) -> 尚未记录买入
A19: =DATE(2027,11,总览!$E$4) -> 46701 | B19: =回撤计划!J22 -> 500 | C19: =B19*总览!$B$8 -> 450 | D19: =B19*总览!$B$9 -> 50 | E19: =B19*总览!$B$10 -> 0 | F19: =SUMIFS(交易记录!$D$6:$D$605,交易记录!$A$6:$A$605,">="&DATE(YEAR(A19),MONTH(A19),1),交易记录!$A$6:$A$605,"<"&DATE(YEAR(A19),MONTH(A19)+1,1),交易记录!$B$6:$B$605,"VOO",交易记录!$C$6:$C$605,"买入")+SUMIFS(交易记录!$E$6:$E$605,交易记录!$A$6:$A$605,">="&DATE(YEAR(A19),MONTH(A19),1),交易记录!$A$6:$A$605,"<"&DATE(YEAR(A19),MONTH(A19)+1,1),交易记录!$B$6:$B$605,"VOO",交易记录!$C$6:$C$605,"买入") -> 0 | G19: =SUMIFS(交易记录!$D$6:$D$605,交易记录!$A$6:$A$605,">="&DATE(YEAR(A19),MONTH(A19),1),交易记录!$A$6:$A$605,"<"&DATE(YEAR(A19),MONTH(A19)+1,1),交易记录!$B$6:$B$605,"QQQM",交易记录!$C$6:$C$605,"买入")+SUMIFS(交易记录!$E$6:$E$605,交易记录!$A$6:$A$605,">="&DATE(YEAR(A19),MONTH(A19),1),交易记录!$A$6:$A$605,"<"&DATE(YEAR(A19),MONTH(A19)+1,1),交易记录!$B$6:$B$605,"QQQM",交易记录!$C$6:$C$605,"买入") -> 0 | H19: =SUMIFS(交易记录!$D$6:$D$605,交易记录!$A$6:$A$605,">="&DATE(YEAR(A19),MONTH(A19),1),交易记录!$A$6:$A$605,"<"&DATE(YEAR(A19),MONTH(A19)+1,1),交易记录!$B$6:$B$605,"SMH",交易记录!$C$6:$C$605,"买入")+SUMIFS(交易记录!$E$6:$E$605,交易记录!$A$6:$A$605,">="&DATE(YEAR(A19),MONTH(A19),1),交易记录!$A$6:$A$605,"<"&DATE(YEAR(A19),MONTH(A19)+1,1),交易记录!$B$6:$B$605,"SMH",交易记录!$C$6:$C$605,"买入") -> 0 | I19: =SUM(F19:H19) -> 0 | J19: =IF(I19=0,"",I19-B19) | K19: =IF(I19=0,"尚未记录买入",IF(ABS(J19)<0.01,"已记录预算金额","已记录，金额有差额")) -> 尚未记录买入
A20: =DATE(2027,12,总览!$E$4) -> 46731 | B20: =回撤计划!J23 -> 500 | C20: =B20*总览!$B$8 -> 450 | D20: =B20*总览!$B$9 -> 50 | E20: =B20*总览!$B$10 -> 0 | F20: =SUMIFS(交易记录!$D$6:$D$605,交易记录!$A$6:$A$605,">="&DATE(YEAR(A20),MONTH(A20),1),交易记录!$A$6:$A$605,"<"&DATE(YEAR(A20),MONTH(A20)+1,1),交易记录!$B$6:$B$605,"VOO",交易记录!$C$6:$C$605,"买入")+SUMIFS(交易记录!$E$6:$E$605,交易记录!$A$6:$A$605,">="&DATE(YEAR(A20),MONTH(A20),1),交易记录!$A$6:$A$605,"<"&DATE(YEAR(A20),MONTH(A20)+1,1),交易记录!$B$6:$B$605,"VOO",交易记录!$C$6:$C$605,"买入") -> 0 | G20: =SUMIFS(交易记录!$D$6:$D$605,交易记录!$A$6:$A$605,">="&DATE(YEAR(A20),MONTH(A20),1),交易记录!$A$6:$A$605,"<"&DATE(YEAR(A20),MONTH(A20)+1,1),交易记录!$B$6:$B$605,"QQQM",交易记录!$C$6:$C$605,"买入")+SUMIFS(交易记录!$E$6:$E$605,交易记录!$A$6:$A$605,">="&DATE(YEAR(A20),MONTH(A20),1),交易记录!$A$6:$A$605,"<"&DATE(YEAR(A20),MONTH(A20)+1,1),交易记录!$B$6:$B$605,"QQQM",交易记录!$C$6:$C$605,"买入") -> 0 | H20: =SUMIFS(交易记录!$D$6:$D$605,交易记录!$A$6:$A$605,">="&DATE(YEAR(A20),MONTH(A20),1),交易记录!$A$6:$A$605,"<"&DATE(YEAR(A20),MONTH(A20)+1,1),交易记录!$B$6:$B$605,"SMH",交易记录!$C$6:$C$605,"买入")+SUMIFS(交易记录!$E$6:$E$605,交易记录!$A$6:$A$605,">="&DATE(YEAR(A20),MONTH(A20),1),交易记录!$A$6:$A$605,"<"&DATE(YEAR(A20),MONTH(A20)+1,1),交易记录!$B$6:$B$605,"SMH",交易记录!$C$6:$C$605,"买入") -> 0 | I20: =SUM(F20:H20) -> 0 | J20: =IF(I20=0,"",I20-B20) | K20: =IF(I20=0,"尚未记录买入",IF(ABS(J20)<0.01,"已记录预算金额","已记录，金额有差额")) -> 尚未记录买入
A21: =DATE(2028,1,总览!$E$4) -> 46762 | B21: =回撤计划!J24 -> 500 | C21: =B21*总览!$B$8 -> 450 | D21: =B21*总览!$B$9 -> 50 | E21: =B21*总览!$B$10 -> 0 | F21: =SUMIFS(交易记录!$D$6:$D$605,交易记录!$A$6:$A$605,">="&DATE(YEAR(A21),MONTH(A21),1),交易记录!$A$6:$A$605,"<"&DATE(YEAR(A21),MONTH(A21)+1,1),交易记录!$B$6:$B$605,"VOO",交易记录!$C$6:$C$605,"买入")+SUMIFS(交易记录!$E$6:$E$605,交易记录!$A$6:$A$605,">="&DATE(YEAR(A21),MONTH(A21),1),交易记录!$A$6:$A$605,"<"&DATE(YEAR(A21),MONTH(A21)+1,1),交易记录!$B$6:$B$605,"VOO",交易记录!$C$6:$C$605,"买入") -> 0 | G21: =SUMIFS(交易记录!$D$6:$D$605,交易记录!$A$6:$A$605,">="&DATE(YEAR(A21),MONTH(A21),1),交易记录!$A$6:$A$605,"<"&DATE(YEAR(A21),MONTH(A21)+1,1),交易记录!$B$6:$B$605,"QQQM",交易记录!$C$6:$C$605,"买入")+SUMIFS(交易记录!$E$6:$E$605,交易记录!$A$6:$A$605,">="&DATE(YEAR(A21),MONTH(A21),1),交易记录!$A$6:$A$605,"<"&DATE(YEAR(A21),MONTH(A21)+1,1),交易记录!$B$6:$B$605,"QQQM",交易记录!$C$6:$C$605,"买入") -> 0 | H21: =SUMIFS(交易记录!$D$6:$D$605,交易记录!$A$6:$A$605,">="&DATE(YEAR(A21),MONTH(A21),1),交易记录!$A$6:$A$605,"<"&DATE(YEAR(A21),MONTH(A21)+1,1),交易记录!$B$6:$B$605,"SMH",交易记录!$C$6:$C$605,"买入")+SUMIFS(交易记录!$E$6:$E$605,交易记录!$A$6:$A$605,">="&DATE(YEAR(A21),MONTH(A21),1),交易记录!$A$6:$A$605,"<"&DATE(YEAR(A21),MONTH(A21)+1,1),交易记录!$B$6:$B$605,"SMH",交易记录!$C$6:$C$605,"买入") -> 0 | I21: =SUM(F21:H21) -> 0 | J21: =IF(I21=0,"",I21-B21) | K21: =IF(I21=0,"尚未记录买入",IF(ABS(J21)<0.01,"已记录预算金额","已记录，金额有差额")) -> 尚未记录买入
A22: =DATE(2028,2,总览!$E$4) -> 46793 | B22: =回撤计划!J25 -> 500 | C22: =B22*总览!$B$8 -> 450 | D22: =B22*总览!$B$9 -> 50 | E22: =B22*总览!$B$10 -> 0 | F22: =SUMIFS(交易记录!$D$6:$D$605,交易记录!$A$6:$A$605,">="&DATE(YEAR(A22),MONTH(A22),1),交易记录!$A$6:$A$605,"<"&DATE(YEAR(A22),MONTH(A22)+1,1),交易记录!$B$6:$B$605,"VOO",交易记录!$C$6:$C$605,"买入")+SUMIFS(交易记录!$E$6:$E$605,交易记录!$A$6:$A$605,">="&DATE(YEAR(A22),MONTH(A22),1),交易记录!$A$6:$A$605,"<"&DATE(YEAR(A22),MONTH(A22)+1,1),交易记录!$B$6:$B$605,"VOO",交易记录!$C$6:$C$605,"买入") -> 0 | G22: =SUMIFS(交易记录!$D$6:$D$605,交易记录!$A$6:$A$605,">="&DATE(YEAR(A22),MONTH(A22),1),交易记录!$A$6:$A$605,"<"&DATE(YEAR(A22),MONTH(A22)+1,1),交易记录!$B$6:$B$605,"QQQM",交易记录!$C$6:$C$605,"买入")+SUMIFS(交易记录!$E$6:$E$605,交易记录!$A$6:$A$605,">="&DATE(YEAR(A22),MONTH(A22),1),交易记录!$A$6:$A$605,"<"&DATE(YEAR(A22),MONTH(A22)+1,1),交易记录!$B$6:$B$605,"QQQM",交易记录!$C$6:$C$605,"买入") -> 0 | H22: =SUMIFS(交易记录!$D$6:$D$605,交易记录!$A$6:$A$605,">="&DATE(YEAR(A22),MONTH(A22),1),交易记录!$A$6:$A$605,"<"&DATE(YEAR(A22),MONTH(A22)+1,1),交易记录!$B$6:$B$605,"SMH",交易记录!$C$6:$C$605,"买入")+SUMIFS(交易记录!$E$6:$E$605,交易记录!$A$6:$A$605,">="&DATE(YEAR(A22),MONTH(A22),1),交易记录!$A$6:$A$605,"<"&DATE(YEAR(A22),MONTH(A22)+1,1),交易记录!$B$6:$B$605,"SMH",交易记录!$C$6:$C$605,"买入") -> 0 | I22: =SUM(F22:H22) -> 0 | J22: =IF(I22=0,"",I22-B22) | K22: =IF(I22=0,"尚未记录买入",IF(ABS(J22)<0.01,"已记录预算金额","已记录，金额有差额")) -> 尚未记录买入
A23: =DATE(2028,3,总览!$E$4) -> 46822 | B23: =回撤计划!J26 -> 500 | C23: =B23*总览!$B$8 -> 450 | D23: =B23*总览!$B$9 -> 50 | E23: =B23*总览!$B$10 -> 0 | F23: =SUMIFS(交易记录!$D$6:$D$605,交易记录!$A$6:$A$605,">="&DATE(YEAR(A23),MONTH(A23),1),交易记录!$A$6:$A$605,"<"&DATE(YEAR(A23),MONTH(A23)+1,1),交易记录!$B$6:$B$605,"VOO",交易记录!$C$6:$C$605,"买入")+SUMIFS(交易记录!$E$6:$E$605,交易记录!$A$6:$A$605,">="&DATE(YEAR(A23),MONTH(A23),1),交易记录!$A$6:$A$605,"<"&DATE(YEAR(A23),MONTH(A23)+1,1),交易记录!$B$6:$B$605,"VOO",交易记录!$C$6:$C$605,"买入") -> 0 | G23: =SUMIFS(交易记录!$D$6:$D$605,交易记录!$A$6:$A$605,">="&DATE(YEAR(A23),MONTH(A23),1),交易记录!$A$6:$A$605,"<"&DATE(YEAR(A23),MONTH(A23)+1,1),交易记录!$B$6:$B$605,"QQQM",交易记录!$C$6:$C$605,"买入")+SUMIFS(交易记录!$E$6:$E$605,交易记录!$A$6:$A$605,">="&DATE(YEAR(A23),MONTH(A23),1),交易记录!$A$6:$A$605,"<"&DATE(YEAR(A23),MONTH(A23)+1,1),交易记录!$B$6:$B$605,"QQQM",交易记录!$C$6:$C$605,"买入") -> 0 | H23: =SUMIFS(交易记录!$D$6:$D$605,交易记录!$A$6:$A$605,">="&DATE(YEAR(A23),MONTH(A23),1),交易记录!$A$6:$A$605,"<"&DATE(YEAR(A23),MONTH(A23)+1,1),交易记录!$B$6:$B$605,"SMH",交易记录!$C$6:$C$605,"买入")+SUMIFS(交易记录!$E$6:$E$605,交易记录!$A$6:$A$605,">="&DATE(YEAR(A23),MONTH(A23),1),交易记录!$A$6:$A$605,"<"&DATE(YEAR(A23),MONTH(A23)+1,1),交易记录!$B$6:$B$605,"SMH",交易记录!$C$6:$C$605,"买入") -> 0 | I23: =SUM(F23:H23) -> 0 | J23: =IF(I23=0,"",I23-B23) | K23: =IF(I23=0,"尚未记录买入",IF(ABS(J23)<0.01,"已记录预算金额","已记录，金额有差额")) -> 尚未记录买入
A24: =DATE(2028,4,总览!$E$4) -> 46853 | B24: =回撤计划!J27 -> 500 | C24: =B24*总览!$B$8 -> 450 | D24: =B24*总览!$B$9 -> 50 | E24: =B24*总览!$B$10 -> 0 | F24: =SUMIFS(交易记录!$D$6:$D$605,交易记录!$A$6:$A$605,">="&DATE(YEAR(A24),MONTH(A24),1),交易记录!$A$6:$A$605,"<"&DATE(YEAR(A24),MONTH(A24)+1,1),交易记录!$B$6:$B$605,"VOO",交易记录!$C$6:$C$605,"买入")+SUMIFS(交易记录!$E$6:$E$605,交易记录!$A$6:$A$605,">="&DATE(YEAR(A24),MONTH(A24),1),交易记录!$A$6:$A$605,"<"&DATE(YEAR(A24),MONTH(A24)+1,1),交易记录!$B$6:$B$605,"VOO",交易记录!$C$6:$C$605,"买入") -> 0 | G24: =SUMIFS(交易记录!$D$6:$D$605,交易记录!$A$6:$A$605,">="&DATE(YEAR(A24),MONTH(A24),1),交易记录!$A$6:$A$605,"<"&DATE(YEAR(A24),MONTH(A24)+1,1),交易记录!$B$6:$B$605,"QQQM",交易记录!$C$6:$C$605,"买入")+SUMIFS(交易记录!$E$6:$E$605,交易记录!$A$6:$A$605,">="&DATE(YEAR(A24),MONTH(A24),1),交易记录!$A$6:$A$605,"<"&DATE(YEAR(A24),MONTH(A24)+1,1),交易记录!$B$6:$B$605,"QQQM",交易记录!$C$6:$C$605,"买入") -> 0 | H24: =SUMIFS(交易记录!$D$6:$D$605,交易记录!$A$6:$A$605,">="&DATE(YEAR(A24),MONTH(A24),1),交易记录!$A$6:$A$605,"<"&DATE(YEAR(A24),MONTH(A24)+1,1),交易记录!$B$6:$B$605,"SMH",交易记录!$C$6:$C$605,"买入")+SUMIFS(交易记录!$E$6:$E$605,交易记录!$A$6:$A$605,">="&DATE(YEAR(A24),MONTH(A24),1),交易记录!$A$6:$A$605,"<"&DATE(YEAR(A24),MONTH(A24)+1,1),交易记录!$B$6:$B$605,"SMH",交易记录!$C$6:$C$605,"买入") -> 0 | I24: =SUM(F24:H24) -> 0 | J24: =IF(I24=0,"",I24-B24) | K24: =IF(I24=0,"尚未记录买入",IF(ABS(J24)<0.01,"已记录预算金额","已记录，金额有差额")) -> 尚未记录买入
A25: =DATE(2028,5,总览!$E$4) -> 46883 | B25: =回撤计划!J28 -> 500 | C25: =B25*总览!$B$8 -> 450 | D25: =B25*总览!$B$9 -> 50 | E25: =B25*总览!$B$10 -> 0 | F25: =SUMIFS(交易记录!$D$6:$D$605,交易记录!$A$6:$A$605,">="&DATE(YEAR(A25),MONTH(A25),1),交易记录!$A$6:$A$605,"<"&DATE(YEAR(A25),MONTH(A25)+1,1),交易记录!$B$6:$B$605,"VOO",交易记录!$C$6:$C$605,"买入")+SUMIFS(交易记录!$E$6:$E$605,交易记录!$A$6:$A$605,">="&DATE(YEAR(A25),MONTH(A25),1),交易记录!$A$6:$A$605,"<"&DATE(YEAR(A25),MONTH(A25)+1,1),交易记录!$B$6:$B$605,"VOO",交易记录!$C$6:$C$605,"买入") -> 0 | G25: =SUMIFS(交易记录!$D$6:$D$605,交易记录!$A$6:$A$605,">="&DATE(YEAR(A25),MONTH(A25),1),交易记录!$A$6:$A$605,"<"&DATE(YEAR(A25),MONTH(A25)+1,1),交易记录!$B$6:$B$605,"QQQM",交易记录!$C$6:$C$605,"买入")+SUMIFS(交易记录!$E$6:$E$605,交易记录!$A$6:$A$605,">="&DATE(YEAR(A25),MONTH(A25),1),交易记录!$A$6:$A$605,"<"&DATE(YEAR(A25),MONTH(A25)+1,1),交易记录!$B$6:$B$605,"QQQM",交易记录!$C$6:$C$605,"买入") -> 0 | H25: =SUMIFS(交易记录!$D$6:$D$605,交易记录!$A$6:$A$605,">="&DATE(YEAR(A25),MONTH(A25),1),交易记录!$A$6:$A$605,"<"&DATE(YEAR(A25),MONTH(A25)+1,1),交易记录!$B$6:$B$605,"SMH",交易记录!$C$6:$C$605,"买入")+SUMIFS(交易记录!$E$6:$E$605,交易记录!$A$6:$A$605,">="&DATE(YEAR(A25),MONTH(A25),1),交易记录!$A$6:$A$605,"<"&DATE(YEAR(A25),MONTH(A25)+1,1),交易记录!$B$6:$B$605,"SMH",交易记录!$C$6:$C$605,"买入") -> 0 | I25: =SUM(F25:H25) -> 0 | J25: =IF(I25=0,"",I25-B25) | K25: =IF(I25=0,"尚未记录买入",IF(ABS(J25)<0.01,"已记录预算金额","已记录，金额有差额")) -> 尚未记录买入
A26: =DATE(2028,6,总览!$E$4) -> 46914 | B26: =回撤计划!J29 -> 500 | C26: =B26*总览!$B$8 -> 450 | D26: =B26*总览!$B$9 -> 50 | E26: =B26*总览!$B$10 -> 0 | F26: =SUMIFS(交易记录!$D$6:$D$605,交易记录!$A$6:$A$605,">="&DATE(YEAR(A26),MONTH(A26),1),交易记录!$A$6:$A$605,"<"&DATE(YEAR(A26),MONTH(A26)+1,1),交易记录!$B$6:$B$605,"VOO",交易记录!$C$6:$C$605,"买入")+SUMIFS(交易记录!$E$6:$E$605,交易记录!$A$6:$A$605,">="&DATE(YEAR(A26),MONTH(A26),1),交易记录!$A$6:$A$605,"<"&DATE(YEAR(A26),MONTH(A26)+1,1),交易记录!$B$6:$B$605,"VOO",交易记录!$C$6:$C$605,"买入") -> 0 | G26: =SUMIFS(交易记录!$D$6:$D$605,交易记录!$A$6:$A$605,">="&DATE(YEAR(A26),MONTH(A26),1),交易记录!$A$6:$A$605,"<"&DATE(YEAR(A26),MONTH(A26)+1,1),交易记录!$B$6:$B$605,"QQQM",交易记录!$C$6:$C$605,"买入")+SUMIFS(交易记录!$E$6:$E$605,交易记录!$A$6:$A$605,">="&DATE(YEAR(A26),MONTH(A26),1),交易记录!$A$6:$A$605,"<"&DATE(YEAR(A26),MONTH(A26)+1,1),交易记录!$B$6:$B$605,"QQQM",交易记录!$C$6:$C$605,"买入") -> 0 | H26: =SUMIFS(交易记录!$D$6:$D$605,交易记录!$A$6:$A$605,">="&DATE(YEAR(A26),MONTH(A26),1),交易记录!$A$6:$A$605,"<"&DATE(YEAR(A26),MONTH(A26)+1,1),交易记录!$B$6:$B$605,"SMH",交易记录!$C$6:$C$605,"买入")+SUMIFS(交易记录!$E$6:$E$605,交易记录!$A$6:$A$605,">="&DATE(YEAR(A26),MONTH(A26),1),交易记录!$A$6:$A$605,"<"&DATE(YEAR(A26),MONTH(A26)+1,1),交易记录!$B$6:$B$605,"SMH",交易记录!$C$6:$C$605,"买入") -> 0 | I26: =SUM(F26:H26) -> 0 | J26: =IF(I26=0,"",I26-B26) | K26: =IF(I26=0,"尚未记录买入",IF(ABS(J26)<0.01,"已记录预算金额","已记录，金额有差额")) -> 尚未记录买入
A27: =DATE(2028,7,总览!$E$4) -> 46944 | B27: =回撤计划!J30 -> 500 | C27: =B27*总览!$B$8 -> 450 | D27: =B27*总览!$B$9 -> 50 | E27: =B27*总览!$B$10 -> 0 | F27: =SUMIFS(交易记录!$D$6:$D$605,交易记录!$A$6:$A$605,">="&DATE(YEAR(A27),MONTH(A27),1),交易记录!$A$6:$A$605,"<"&DATE(YEAR(A27),MONTH(A27)+1,1),交易记录!$B$6:$B$605,"VOO",交易记录!$C$6:$C$605,"买入")+SUMIFS(交易记录!$E$6:$E$605,交易记录!$A$6:$A$605,">="&DATE(YEAR(A27),MONTH(A27),1),交易记录!$A$6:$A$605,"<"&DATE(YEAR(A27),MONTH(A27)+1,1),交易记录!$B$6:$B$605,"VOO",交易记录!$C$6:$C$605,"买入") -> 0 | G27: =SUMIFS(交易记录!$D$6:$D$605,交易记录!$A$6:$A$605,">="&DATE(YEAR(A27),MONTH(A27),1),交易记录!$A$6:$A$605,"<"&DATE(YEAR(A27),MONTH(A27)+1,1),交易记录!$B$6:$B$605,"QQQM",交易记录!$C$6:$C$605,"买入")+SUMIFS(交易记录!$E$6:$E$605,交易记录!$A$6:$A$605,">="&DATE(YEAR(A27),MONTH(A27),1),交易记录!$A$6:$A$605,"<"&DATE(YEAR(A27),MONTH(A27)+1,1),交易记录!$B$6:$B$605,"QQQM",交易记录!$C$6:$C$605,"买入") -> 0 | H27: =SUMIFS(交易记录!$D$6:$D$605,交易记录!$A$6:$A$605,">="&DATE(YEAR(A27),MONTH(A27),1),交易记录!$A$6:$A$605,"<"&DATE(YEAR(A27),MONTH(A27)+1,1),交易记录!$B$6:$B$605,"SMH",交易记录!$C$6:$C$605,"买入")+SUMIFS(交易记录!$E$6:$E$605,交易记录!$A$6:$A$605,">="&DATE(YEAR(A27),MONTH(A27),1),交易记录!$A$6:$A$605,"<"&DATE(YEAR(A27),MONTH(A27)+1,1),交易记录!$B$6:$B$605,"SMH",交易记录!$C$6:$C$605,"买入") -> 0 | I27: =SUM(F27:H27) -> 0 | J27: =IF(I27=0,"",I27-B27) | K27: =IF(I27=0,"尚未记录买入",IF(ABS(J27)<0.01,"已记录预算金额","已记录，金额有差额")) -> 尚未记录买入
A28: =DATE(2028,8,总览!$E$4) -> 46975 | B28: =回撤计划!J31 -> 500 | C28: =B28*总览!$B$8 -> 450 | D28: =B28*总览!$B$9 -> 50 | E28: =B28*总览!$B$10 -> 0 | F28: =SUMIFS(交易记录!$D$6:$D$605,交易记录!$A$6:$A$605,">="&DATE(YEAR(A28),MONTH(A28),1),交易记录!$A$6:$A$605,"<"&DATE(YEAR(A28),MONTH(A28)+1,1),交易记录!$B$6:$B$605,"VOO",交易记录!$C$6:$C$605,"买入")+SUMIFS(交易记录!$E$6:$E$605,交易记录!$A$6:$A$605,">="&DATE(YEAR(A28),MONTH(A28),1),交易记录!$A$6:$A$605,"<"&DATE(YEAR(A28),MONTH(A28)+1,1),交易记录!$B$6:$B$605,"VOO",交易记录!$C$6:$C$605,"买入") -> 0 | G28: =SUMIFS(交易记录!$D$6:$D$605,交易记录!$A$6:$A$605,">="&DATE(YEAR(A28),MONTH(A28),1),交易记录!$A$6:$A$605,"<"&DATE(YEAR(A28),MONTH(A28)+1,1),交易记录!$B$6:$B$605,"QQQM",交易记录!$C$6:$C$605,"买入")+SUMIFS(交易记录!$E$6:$E$605,交易记录!$A$6:$A$605,">="&DATE(YEAR(A28),MONTH(A28),1),交易记录!$A$6:$A$605,"<"&DATE(YEAR(A28),MONTH(A28)+1,1),交易记录!$B$6:$B$605,"QQQM",交易记录!$C$6:$C$605,"买入") -> 0 | H28: =SUMIFS(交易记录!$D$6:$D$605,交易记录!$A$6:$A$605,">="&DATE(YEAR(A28),MONTH(A28),1),交易记录!$A$6:$A$605,"<"&DATE(YEAR(A28),MONTH(A28)+1,1),交易记录!$B$6:$B$605,"SMH",交易记录!$C$6:$C$605,"买入")+SUMIFS(交易记录!$E$6:$E$605,交易记录!$A$6:$A$605,">="&DATE(YEAR(A28),MONTH(A28),1),交易记录!$A$6:$A$605,"<"&DATE(YEAR(A28),MONTH(A28)+1,1),交易记录!$B$6:$B$605,"SMH",交易记录!$C$6:$C$605,"买入") -> 0 | I28: =SUM(F28:H28) -> 0 | J28: =IF(I28=0,"",I28-B28) | K28: =IF(I28=0,"尚未记录买入",IF(ABS(J28)<0.01,"已记录预算金额","已记录，金额有差额")) -> 尚未记录买入
